Workbook

Sheet compare_results_1_nodes
A1: experiment | B1: n_nodes | C1: duration_dp | D1: solution_dp | E1: optimal_dp | F1: duration_iqcp | G1: solution_iqcp | H1: optimal_iqcp | I1: duration_ilp | J1: solution_ilp | K1: optimal_ilp | L1: duration_miqcp | M1: solution_miqcp | N1: optimal_miqcp | O1: duration_greedy | P1: solution_greedy | Q1: optimal_greedy | R1: solution_rollout k=1 | S1: time_taken k=1 | T1: optimal_rollout k=1 | U1: diff_iqcp_rollout k=1 | V1: diff_greedy_rollout k=1 | W1: solution_rollout k=2 | X1: time_taken k=2 | Y1: optimal_rollout k=2 | Z1: diff_iqcp_rollout k=2 | AA1: diff_greedy_rollout k=2 | AB1: solution_rollout k=3 | AC1: time_taken k=3 | AD1: optimal_rollout k=3 | AE1: diff_iqcp_rollout k=3 | AF1: diff_greedy_rollout k=3
A2: 10 | B2: 25 | C2: 0.11955214 | D2: [-1, 15, 12, 11, 22] | E2: 20 | F2: 8.4801874 | G2: [-1, 15, 13, 5, 17] | H2: 20 | I2: 30.69507 | J2: [-1, 15, 13, 5, 17] | K2: 20 | L2: 86400.117 | O2: 0.0041575432 | P2: [-1, 13, 14, 3] | Q2: 12 | R2: [15, 12, 11, 22] | S2: 0.064846167 | T2: 20 | U2: 0 | V2: 8 | W2: [15, 12, 11, 22] | X2: 0.12355775 | Y2: 20 | Z2: 0 | AA2: 8 | AB2: [15, 12, 11, 22] | AC2: 0.19009912 | AD2: 20 | AE2: 0 | AF2: 8
A3: 11 | B3: 40 | C3: 756.5457 | D3: [-1, 38, 26, 11, 15, 7, 8] | E3: 36 | F3: 78.926251 | G3: [-1, 38, 26, 11, 15, 8, 7] | H3: 36 | I3: 336.39173 | J3: [-1, 38, 32, 33, 8, 7] | K3: 36 | O3: 0.0050559044 | P3: [-1, 26, 35, 4] | Q3: 31 | R3: [38, 32, 33, 8, 7] | S3: 0.16860275 | T3: 36 | U3: 0 | V3: 5 | W3: [38, 32, 33, 8, 7] | X3: 0.82291654 | Y3: 36 | Z3: 0 | AA3: 5 | AB3: [38, 32, 33, 8, 7] | AC3: 2.4259862 | AD3: 36 | AE3: 0 | AF3: 5
A4: 37 | B4: 75 | F4: 859.7922 | G4: [-1, 5, 63, 50, 29] | H4: 69 | I4: 1054.3818 | O4: 0.0069537163 | P4: [-1, 5, 29] | Q4: 65 | R4: [50, 63, 5, 29] | S4: 1.9745873 | T4: 69 | U4: 0 | V4: 4 | W4: [50, 63, 5, 29] | X4: 25.696464 | Y4: 69 | Z4: 0 | AA4: 4 | AB4: [50, 63, 5, 29] | AC4: 159.59677 | AD4: 69 | AE4: 0 | AF4: 4
A5: 48 | B5: 100 | F5: 6326.9703 | G5: [-1, 74, 62, 17, 43] | H5: 89 | I5: 3379.958 | O5: 0.0090699196 | P5: [-1, 6, 41, 81] | Q5: 86 | R5: [74, 17, 62, 43] | S5: 1.235143 | T5: 89 | U5: 0 | V5: 3 | W5: [74, 17, 62, 43] | X5: 3.3276985 | Y5: 89 | Z5: 0 | AA5: 3 | AB5: [74, 17, 62, 43] | AC5: 87.265396 | AD5: 89 | AE5: 0 | AF5: 3
A6: 52 | B6: 20 | C6: 0.058469057 | D6: [-1, 6, 3, 1, 8, 4, 2] | E6: 15 | F6: 5.6918812 | G6: [-1, 6, 3, 8, 1, 9] | H6: 15 | I6: 23.852616 | J6: [-1, 6, 3, 19, 12, 17] | K6: 15 | L6: 86400.179 | O6: 0.0037240982 | P6: [-1, 6, 19, 12, 17] | Q6: 13 | R6: [6, 3, 19, 12, 17] | S6: 0.0578075 | T6: 15 | U6: 0 | V6: 2 | W6: [6, 3, 19, 12, 17] | X6: 0.09065975 | Y6: 15 | Z6: 0 | AA6: 2 | AB6: [6, 3, 19, 12, 17] | AC6: 0.16066162 | AD6: 15 | AE6: 0 | AF6: 2
A7: 24 | B7: 50 | F7: 132.75861 | G7: [-1, 5, 6, 25, 21, 37, 40] | H7: 48 | I7: 429.64812 | J7: [-1, 5, 6, 25, 21, 40, 37] | K7: 48 | O7: 0.0060706139 | P7: [-1, 5, 21, 25, 37, 40] | Q7: 46 | R7: [6, 11, 10, 14, 43] | S7: 0.38118025 | T7: 48 | U7: 0 | V7: 2 | W7: [5, 6, 25, 21, 37, 40] | X7: 2.7484046 | Y7: 48 | Z7: 0 | AA7: 2 | AB7: [11, 6, 10, 14, 43] | AC7: 18.026117 | AD7: 48 | AE7: 0 | AF7: 2
A8: 47 | B8: 100 | F8: 2488.1506 | G8: [-1, 0, 54, 92, 16] | H8: 97 | I8: 3088.3285 | O8: 0.0094974041 | P8: [-1, 0, 16, 63, 7] | Q8: 95 | R8: [0, 54, 92, 16] | S8: 1.242258 | T8: 97 | U8: 0 | V8: 2 | W8: [0, 54, 92, 16] | X8: 43.969725 | Y8: 97 | Z8: 0 | AA8: 2 | AB8: [0, 54, 92, 16] | AC8: 156.99346 | AD8: 97 | AE8: 0 | AF8: 2
A9: 41 | B9: 100 | F9: 3565.7876 | G9: [-1, 58, 29, 38] | H9: 99 | I9: 4040.3333 | O9: 0.009118557 | P9: [-1, 38] | Q9: 97 | R9: [58, 29, 38] | S9: 4.4783545 | T9: 99 | U9: 0 | V9: 2 | W9: [58, 29, 38] | X9: 105.60224 | Y9: 99 | Z9: 0 | AA9: 2 | AB9: [58, 29, 38] | AC9: 899.17825 | AD9: 99 | AE9: 0 | AF9: 2
A10: 53 | B10: 20 | C10: 0.02071476 | D10: [-1, 10, 2, 1] | E10: 15 | F10: 3.139914 | G10: [-1, 10, 2, 1] | H10: 15 | I10: 7.6340013 | J10: [-1, 10, 2, 1] | K10: 15 | L10: 94.903299 | M10: [-1, 10, 2, 1, 19, 5, 0, 4, 6, 13, 12] | N10: 15 | O10: 0.0036454201 | P10: [-1, 10, 1] | Q10: 14 | R10: [10, 2, 1] | S10: 0.039888125 | T10: 15 | U10: 0 | V10: 1 | W10: [10, 2, 1] | X10: 0.05805 | Y10: 15 | Z10: 0 | AA10: 1 | AB10: [10, 2, 1] | AC10: 0.088539542 | AD10: 15 | AE10: 0 | AF10: 1
A11: 2 | B11: 25 | C11: 0.15577698 | D11: [-1, 18, 19, 21] | E11: 20 | F11: 5.0183191 | G11: [-1, 18, 21, 19] | H11: 20 | I11: 17.926093 | J11: [-1, 18, 21, 19] | K11: 20 | L11: 86400.072 | O11: 0.004509449 | P11: [-1, 1, 6] | Q11: 19 | R11: [18, 21, 19] | S11: 0.053255167 | T11: 20 | U11: 0 | V11: 1 | W11: [18, 21, 19] | X11: 0.17472088 | Y11: 20 | Z11: 0 | AA11: 1 | AB11: [18, 21, 19] | AC11: 0.24558804 | AD11: 20 | AE11: 0 | AF11: 1
A12: 26 | B12: 50 | F12: 130.10778 | G12: [-1, 12, 36, 26] | H12: 45 | I12: 602.71775 | J12: [-1, 12, 36, 26] | K12: 45 | O12: 0.0056357384 | P12: [-1, 12, 26] | Q12: 44 | R12: [12, 36, 26] | S12: 0.28343675 | T12: 45 | U12: 0 | V12: 1 | W12: [12, 36, 26] | X12: 4.3689845 | Y12: 45 | Z12: 0 | AA12: 1 | AB12: [12, 36, 26] | AC12: 15.811426 | AD12: 45 | AE12: 0 | AF12: 1
A13: 22 | B13: 50 | F13: 68.101652 | G13: [-1, 20, 49, 8] | H13: 49 | I13: 188.78203 | J13: [-1, 20, 49, 8] | K13: 49 | O13: 0.005525589 | P13: [-1, 8, 20] | Q13: 48 | R13: [20, 49, 8] | S13: 0.40008525 | T13: 49 | U13: 0 | V13: 1 | W13: [20, 49, 8] | X13: 4.7785656 | Y13: 49 | Z13: 0 | AA13: 1 | AB13: [20, 49, 8] | AC13: 13.621834 | AD13: 49 | AE13: 0 | AF13: 1
A14: 33 | B14: 75 | F14: 862.76423 | G14: [-1, 68, 30, 53] | H14: 72 | I14: 1056.4615 | O14: 0.0074980259 | P14: [-1, 68, 53] | Q14: 71 | R14: [68, 30, 53] | S14: 0.82913062 | T14: 72 | U14: 0 | V14: 1 | W14: [68, 30, 53] | X14: 25.060403 | Y14: 72 | Z14: 0 | AA14: 1 | AB14: [68, 30, 53] | AC14: 177.60295 | AD14: 72 | AE14: 0 | AF14: 1
A15: 44 | B15: 100 | F15: 3300.5156 | G15: [-1, 3, 22, 16] | H15: 98 | I15: 3691.829 | O15: 0.0086023808 | P15: [-1, 22, 16, 62] | Q15: 97 | R15: [3, 22, 16] | S15: 1.677113 | T15: 98 | U15: 0 | V15: 1 | W15: [3, 22, 16] | X15: 69.539149 | Y15: 98 | Z15: 0 | AA15: 1 | AB15: [3, 22, 16] | AC15: 681.20098 | AD15: 98 | AE15: 0 | AF15: 1
A16: 43 | B16: 100 | F16: 2591.8491 | G16: [-1, 12, 68, 98, 35] | H16: 96 | I16: 3170.6342 | O16: 0.0089905262 | P16: [-1, 68, 12, 98, 93] | Q16: 95 | R16: [12, 68, 98, 35] | S16: 2.6676563 | T16: 96 | U16: 0 | V16: 1 | W16: [12, 68, 98, 35] | X16: 95.267819 | Y16: 96 | Z16: 0 | AA16: 1 | AB16: [12, 68, 98, 35] | AC16: 331.37684 | AD16: 96 | AE16: 0 | AF16: 1
A17: 49 | B17: 100 | F17: 2521.6156 | G17: [-1, 99, 86, 47] | H17: 98 | I17: 3149.4038 | O17: 0.0088615417 | P17: [-1, 86, 47, 72] | Q17: 97 | R17: [99, 86, 47] | S17: 2.9854539 | T17: 98 | U17: 0 | V17: 1 | W17: [99, 86, 47] | X17: 44.019742 | Y17: 98 | Z17: 0 | AA17: 1 | AB17: [99, 86, 47] | AC17: 549.05003 | AD17: 98 | AE17: 0 | AF17: 1
A18: 5 | B18: 25 | C18: 1.7921865 | D18: [-1, 8] | E18: 22 | F18: 10.067082 | G18: [-1, 8] | H18: 22 | I18: 20.000447 | J18: [-1, 8] | K18: 22 | L18: 43438.653 | M18: [-1, 8, 24, 21, 20] | N18: 22 | O18: 0.0041453838 | P18: [-1, 8] | Q18: 22 | R18: [8] | S18: 0.020007292 | T18: 22 | U18: 0 | V18: 0 | W18: [8] | X18: 0.12626475 | Y18: 22 | Z18: 0 | AA18: 0 | AB18: [8] | AC18: 0.18059608 | AD18: 22 | AE18: 0 | AF18: 0
A19: 3 | B19: 25 | C19: 3.4204645 | D19: [-1, 10] | E19: 21 | F19: 10.010939 | G19: [-1, 10] | H19: 21 | I19: 17.00809 | J19: [-1, 10] | K19: 21 | L19: 1425.4224 | M19: [-1, 10] | N19: 21 | O19: 0.0040242672 | P19: [-1, 10] | Q19: 21 | R19: [10] | S19: 0.027863166 | T19: 21 | U19: 0 | V19: 0 | W19: [10] | X19: 0.10382533 | Y19: 21 | Z19: 0 | AA19: 0 | AB19: [10] | AC19: 0.26194842 | AD19: 21 | AE19: 0 | AF19: 0
A20: 60 | B20: 20 | C20: 0.043447018 | D20: [-1, 4, 1] | E20: 16 | F20: 4.0671201 | G20: [-1, 4, 1] | H20: 16 | I20: 12.392312 | J20: [-1, 4, 1] | K20: 16 | L20: 86400.285 | O20: 0.0038189888 | P20: [-1, 4, 1] | Q20: 16 | R20: [4, 1] | S20: 0.028228875 | T20: 16 | U20: 0 | V20: 0 | W20: [4, 1] | X20: 0.053727833 | Y20: 16 | Z20: 0 | AA20: 0 | AB20: [4, 1] | AC20: 0.093913084 | AD20: 16 | AE20: 0 | AF20: 0
A21: 54 | B21: 20 | C21: 0.030108929 | D21: [-1, 15, 4] | E21: 15 | F21: 3.1323459 | G21: [-1, 15, 4] | H21: 15 | I21: 6.0626445 | J21: [-1, 15, 4] | K21: 15 | L21: 456.62761 | M21: [-1, 15, 4, 16, 11, 0] | N21: 15 | O21: 0.0035321712 | P21: [-1, 15, 4] | Q21: 15 | R21: [15, 4] | S21: 0.028433917 | T21: 15 | U21: 0 | V21: 0 | W21: [15, 4] | X21: 0.054628792 | Y21: 15 | Z21: 0 | AA21: 0 | AB21: [15, 4] | AC21: 0.08802725 | AD21: 15 | AE21: 0 | AF21: 0
A22: 58 | B22: 20 | C22: 0.031080008 | D22: [-1, 3, 6, 8, 5, 18] | E22: 14 | F22: 3.3505523 | G22: [-1, 3, 9, 12] | H22: 14 | I22: 9.3668909 | J22: [-1, 3, 9, 12] | K22: 14 | L22: 86400.115 | O22: 0.0035631657 | P22: [-1, 3, 9, 12] | Q22: 14 | R22: [3, 8, 17] | S22: 0.044324792 | T22: 14 | U22: 0 | V22: 0 | W22: [3, 8, 17] | X22: 0.067796667 | Y22: 14 | Z22: 0 | AA22: 0 | AB22: [3, 8, 17] | AC22: 0.154934 | AD22: 14 | AE22: 0 | AF22: 0
A23: 57 | B23: 20 | C23: 0.14634013 | D23: [-1, 3, 0, 16, 17] | E23: 16 | F23: 6.3730485 | G23: [-1, 3, 14] | H23: 16 | I23: 13.852208 | J23: [-1, 3, 14] | K23: 16 | L23: 86400.153 | O23: 0.0035440922 | P23: [-1, 3, 14] | Q23: 16 | R23: [3, 0, 16, 17] | S23: 0.048121416 | T23: 16 | U23: 0 | V23: 0 | W23: [3, 14] | X23: 0.059643625 | Y23: 16 | Z23: 0 | AA23: 0 | AB23: [3, 0, 16, 17] | AC23: 0.24887813 | AD23: 16 | AE23: 0 | AF23: 0
A24: 6 | B24: 25 | C24: 0.19284844 | D24: [-1, 0, 2, 17] | E24: 19 | F24: 10.538142 | G24: [-1, 0, 2, 17] | H24: 19 | I24: 37.179535 | J24: [-1, 0, 2, 17] | K24: 19 | L24: 86400.036 | O24: 0.0046305656 | P24: [-1, 0, 2, 17] | Q24: 19 | R24: [0, 2, 17] | S24: 0.049223333 | T24: 19 | U24: 0 | V24: 0 | W24: [0, 2, 17] | X24: 0.10428475 | Y24: 19 | Z24: 0 | AA24: 0 | AB24: [0, 2, 17] | AC24: 0.19400329 | AD24: 19 | AE24: 0 | AF24: 0
A25: 8 | B25: 25 | C25: 1.8801317 | D25: [-1, 4, 9, 6, 11, 22] | E25: 19 | F25: 15.032512 | G25: [-1, 4, 17, 13] | H25: 19 | I25: 35.265093 | J25: [-1, 4, 17, 13] | K25: 19 | L25: 86400.196 | O25: 0.0043210983 | P25: [-1, 4, 17, 13] | Q25: 19 | R25: [4, 17, 13] | S25: 0.05192225 | T25: 19 | U25: 0 | V25: 0 | W25: [4, 17, 13] | X25: 0.10405258 | Y25: 19 | Z25: 0 | AA25: 0 | AB25: [4, 17, 13] | AC25: 0.30845104 | AD25: 19 | AE25: 0 | AF25: 0
A26: 7 | B26: 25 | C26: 2.0427024 | D26: [-1, 1, 10, 4, 9, 8] | E26: 18 | F26: 13.685847 | G26: [-1, 7, 10, 8, 9] | H26: 18 | I26: 43.679956 | J26: [-1, 7, 10, 4, 8] | K26: 18 | L26: 86400.141 | O26: 0.004298687 | P26: [-1, 7, 24] | Q26: 18 | R26: [7, 10, 8, 9] | S26: 0.055771708 | T26: 18 | U26: 0 | V26: 0 | W26: [7, 10, 8, 9] | X26: 0.11870592 | Y26: 18 | Z26: 0 | AA26: 0 | AB26: [7, 10, 8, 9] | AC26: 0.29773333 | AD26: 18 | AE26: 0 | AF26: 0
A27: 9 | B27: 25 | C27: 0.31319165 | D27: [-1, 6, 0, 1, 22, 10, 18, 8, 9] | E27: 18 | F27: 27.342374 | G27: [-1, 6, 24, 15, 23] | H27: 18 | I27: 46.145465 | J27: [-1, 6, 24, 23, 15] | K27: 18 | L27: 86400.132 | O27: 0.0044243336 | P27: [-1, 6, 24, 23, 15] | Q27: 18 | R27: [6, 24, 15, 23] | S27: 0.056644583 | T27: 18 | U27: 0 | V27: 0 | W27: [6, 24, 15, 23] | X27: 0.093496291 | Y27: 18 | Z27: 0 | AA27: 0 | AB27: [6, 24, 15, 23] | AC27: 0.1689675 | AD27: 18 | AE27: 0 | AF27: 0
A28: 1 | B28: 25 | C28: 0.17613745 | D28: [-1, 2, 3] | E28: 16 | F28: 13.040887 | G28: [-1, 2, 3] | H28: 16 | I28: 47.843506 | J28: [-1, 2, 23, 19, 21] | K28: 16 | L28: 23232.208 | M28: [-1, 14, 3, 1, 15, 4, 18, 24, 16, 6] | N28: 16 | O28: 0.014831305 | P28: [-1, 2, 3] | Q28: 16 | R28: [23, 2, 21, 19] | S28: 0.063491875 | T28: 16 | U28: 0 | V28: 0 | W28: [23, 2, 21, 19] | X28: 0.14683254 | Y28: 16 | Z28: 0 | AA28: 0 | AB28: [14, 3, 1] | AC28: 0.29684417 | AD28: 16 | AE28: 0 | AF28: 0
A29: 14 | B29: 40 | C29: 2821.6056 | D29: [-1, 13, 6, 12] | E29: 39 | F29: 49.555662 | G29: [-1, 13, 6, 12] | H29: 39 | I29: 110.5152 | J29: [-1, 13, 12, 6] | K29: 39 | O29: 0.0050327778 | P29: [-1, 13, 6, 12] | Q29: 39 | R29: [13, 6, 12] | S29: 0.074470166 | T29: 39 | U29: 0 | V29: 0 | W29: [13, 6, 12] | X29: 0.8872295 | Y29: 39 | Z29: 0 | AA29: 0 | AB29: [13, 6, 12] | AC29: 4.984186 | AD29: 39 | AE29: 0 | AF29: 0
A30: 15 | B30: 40 | C30: 19938.966 | D30: [-1, 28, 7, 13] | E30: 36 | F30: 68.489383 | G30: [-1, 28, 7, 13] | H30: 36 | I30: 240.73659 | J30: [-1, 28, 7, 13] | K30: 36 | O30: 0.0049045086 | P30: [-1, 28, 7, 13] | Q30: 36 | R30: [28, 13, 7] | S30: 0.088303416 | T30: 36 | U30: 0 | V30: 0 | W30: [28, 13, 7] | X30: 0.81283458 | Y30: 36 | Z30: 0 | AA30: 0 | AB30: [28, 13, 7] | AC30: 1.835798 | AD30: 36 | AE30: 0 | AF30: 0
A31: 19 | B31: 40 | C31: 4533.9694 | D31: [-1, 3, 33, 15, 32] | E31: 34 | F31: 43.429265 | G31: [-1, 27, 3] | H31: 34 | I31: 184.54431 | J31: [-1, 27, 3] | K31: 34 | O31: 0.0047674179 | P31: [-1, 27, 3] | Q31: 34 | R31: [27, 33, 4] | S31: 0.09374025 | T31: 34 | U31: 0 | V31: 0 | W31: [27, 33, 4] | X31: 0.79964346 | Y31: 34 | Z31: 0 | AA31: 0 | AB31: [3, 33, 15, 32] | AC31: 3.6631603 | AD31: 34 | AE31: 0 | AF31: 0
A32: 12 | B32: 40 | C32: 10313.59 | D32: [-1, 34] | E32: 36 | F32: 57.669784 | G32: [-1, 34] | H32: 36 | I32: 124.70194 | J32: [-1, 34] | K32: 36 | O32: 0.0047380924 | P32: [-1, 34] | Q32: 36 | R32: [34] | S32: 0.10331875 | T32: 36 | U32: 0 | V32: 0 | W32: [34] | X32: 1.5188525 | Y32: 36 | Z32: 0 | AA32: 0 | AB32: [34] | AC32: 4.3989879 | AD32: 36 | AE32: 0 | AF32: 0
A33: 18 | B33: 40 | C33: 3804.9753 | D33: [-1, 12, 9, 4, 23, 33] | E33: 38 | F33: 57.792312 | G33: [-1, 12, 9, 4, 33, 23] | H33: 38 | I33: 132.33697 | J33: [-1, 12, 9, 4, 33, 23] | K33: 38 | O33: 0.0053415298 | P33: [-1, 12, 9, 4, 23, 33] | Q33: 38 | R33: [12, 37, 16] | S33: 0.11625504 | T33: 38 | U33: 0 | V33: 0 | W33: [12, 37, 16] | X33: 0.87141317 | Y33: 38 | Z33: 0 | AA33: 0 | AB33: [12, 37, 16] | AC33: 3.1248001 | AD33: 38 | AE33: 0 | AF33: 0
A34: 13 | B34: 40 | C34: 86400.276 | F34: 92.590263 | G34: [-1, 7, 24] | H34: 38 | I34: 196.18166 | J34: [-1, 24, 7] | K34: 38 | O34: 0.0048034191 | P34: [-1, 24, 7] | Q34: 38 | R34: [7, 24] | S34: 0.13974788 | T34: 38 | U34: 0 | V34: 0 | W34: [7, 24] | X34: 0.97011229 | Y34: 38 | Z34: 0 | AA34: 0 | AB34: [31, 7, 36, 5, 22] | AC34: 8.9091197 | AD34: 38 | AE34: 0 | AF34: 0
A35: 27 | B35: 50 | F35: 163.08274 | G35: [-1, 19, 1] | H35: 46 | I35: 833.21768 | J35: [-1, 19, 1] | K35: 46 | O35: 0.005720377 | P35: [-1, 19, 1] | Q35: 46 | R35: [19, 1] | S35: 0.15869842 | T35: 46 | U35: 0 | V35: 0 | W35: [19, 1] | X35: 1.9241331 | Y35: 46 | Z35: 0 | AA35: 0 | AB35: [19, 1] | AC35: 4.0078034 | AD35: 46 | AE35: 0 | AF35: 0
A36: 21 | B36: 50 | F36: 148.4857 | G36: [-1, 2, 6, 36] | H36: 46 | I36: 742.77179 | J36: [-1, 2, 6, 36] | K36: 46 | O36: 0.0053641796 | P36: [-1, 2, 6, 36] | Q36: 46 | R36: [2, 6, 36] | S36: 0.16531675 | T36: 46 | U36: 0 | V36: 0 | W36: [2, 6, 36] | X36: 2.4920138 | Y36: 46 | Z36: 0 | AA36: 0 | AB36: [2, 6, 36] | AC36: 18.430154 | AD36: 46 | AE36: 0 | AF36: 0
A37: 20 | B37: 40 | C37: 86402.943 | F37: 75.783719 | G37: [-1, 2, 9] | H37: 36 | I37: 272.98981 | J37: [-1, 2, 9] | K37: 36 | O37: 0.0048246384 | P37: [-1, 2, 9] | Q37: 36 | R37: [9, 2] | S37: 0.20265233 | T37: 36 | U37: 0 | V37: 0 | W37: [9, 2] | X37: 1.67325 | Y37: 36 | Z37: 0 | AA37: 0 | AB37: [9, 2] | AC37: 8.0786281 | AD37: 36 | AE37: 0 | AF37: 0
A38: 30 | B38: 50 | C38: 86400.26 | F38: 155.38067 | G38: [-1, 8, 48, 38] | H38: 44 | I38: 761.49398 | J38: [-1, 8, 48, 38] | K38: 44 | O38: 0.0060241222 | P38: [-1, 8, 48, 38] | Q38: 44 | R38: [8, 48, 38] | S38: 0.20384346 | T38: 44 | U38: 0 | V38: 0 | W38: [8, 48, 38] | X38: 2.0492545 | Y38: 44 | Z38: 0 | AA38: 0 | AB38: [8, 48, 38] | AC38: 6.9343138 | AD38: 44 | AE38: 0 | AF38: 0
A39: 29 | B39: 50 | C39: 86400.255 | F39: 116.93431 | G39: [-1, 32, 6, 35] | H39: 47 | I39: 448.17442 | J39: [-1, 32, 35, 6] | K39: 47 | O39: 0.0055742264 | P39: [-1, 32, 35, 6] | Q39: 47 | R39: [32, 35, 6] | S39: 0.30268154 | T39: 47 | U39: 0 | V39: 0 | W39: [32, 35, 6] | X39: 3.9741486 | Y39: 47 | Z39: 0 | AA39: 0 | AB39: [32, 35, 6] | AC39: 14.789427 | AD39: 47 | AE39: 0 | AF39: 0
A40: 34 | B40: 75 | F40: 797.57794 | G40: [-1, 56, 45, 73] | H40: 74 | I40: 997.39091 | O40: 0.0074398518 | P40: [-1, 73, 56, 45] | Q40: 74 | R40: [73, 56, 45] | S40: 0.43395963 | T40: 74 | U40: 0 | V40: 0 | W40: [73, 56, 45] | X40: 13.930747 | Y40: 74 | Z40: 0 | AA40: 0 | AB40: [73, 56, 45] | AC40: 85.405976 | AD40: 74 | AE40: 0 | AF40: 0
...

Sheet comparaciones
A1: Nodos | B1: Instancias | C1: Prom. Nodos salvados óptimo IQCP | D1: Prom. Nodos salvados Rollout k=1 | E1: Prom. Nodos salvados Rollout k=2 | F1: Prom. Nodos salvados Rollout k=3 | G1: GAP Rollout k=1 | H1: GAP Rollout k=2 | I1: GAP Rollout k=3 | J1: Greedy
A2: 20 | B2: =COUNTIF(compare_results_1_nodes!B:B,comparaciones!A2) -> 10 | C2: =AVERAGEIF(Table2[n_nodes],Table1[[#This Row],[Nodos]],Table2[optimal_iqcp]) -> 14.7 | D2: =AVERAGEIF(Table2[n_nodes],Table1[[#This Row],[Nodos]],Table2[optimal_rollout k=1]) -> 13.8 | E2: =AVERAGEIF(Table2[n_nodes],Table1[[#This Row],[Nodos]],Table2[optimal_rollout k=2]) -> 14.6 | F2: =AVERAGEIF(Table2[n_nodes],Table1[[#This Row],[Nodos]],Table2[optimal_rollout k=3]) -> 14.6 | G2: =((Table1[[#This Row],[Prom. Nodos salvados óptimo IQCP]]-Table1[[#This Row],[Prom. Nodos salvados Rollout k=1]])/Table1[[#This Row],[Prom. Nodos salvados óptimo IQCP]])*100 -> 6.122449 | H2: =((Table1[[#This Row],[Prom. Nodos salvados óptimo IQCP]]-Table1[[#This Row],[Prom. Nodos salvados Rollout k=2]])/Table1[[#This Row],[Prom. Nodos salvados óptimo IQCP]])*100 -> 0.68027211 | I2: =((Table1[[#This Row],[Prom. Nodos salvados óptimo IQCP]]-Table1[[#This Row],[Prom. Nodos salvados Rollout k=3]])/Table1[[#This Row],[Prom. Nodos salvados óptimo IQCP]])*100 -> 0.68027211 | J2: =AVERAGEIF(Table2[n_nodes],Table1[[#This Row],[Nodos]],Table2[optimal_greedy]) -> 13.8
A3: 25 | B3: =COUNTIF(compare_results_1_nodes!B:B,comparaciones!A3) -> 10 | C3: =AVERAGEIF(Table2[n_nodes],Table1[[#This Row],[Nodos]],Table2[optimal_iqcp]) -> 19.1 | D3: =AVERAGEIF(Table2[n_nodes],Table1[[#This Row],[Nodos]],Table2[optimal_rollout k=1]) -> 19 | E3: =AVERAGEIF(Table2[n_nodes],Table1[[#This Row],[Nodos]],Table2[optimal_rollout k=2]) -> 19 | F3: =AVERAGEIF(Table2[n_nodes],Table1[[#This Row],[Nodos]],Table2[optimal_rollout k=3]) -> 19 | G3: =((Table1[[#This Row],[Prom. Nodos salvados óptimo IQCP]]-Table1[[#This Row],[Prom. Nodos salvados Rollout k=1]])/Table1[[#This Row],[Prom. Nodos salvados óptimo IQCP]])*100 -> 0.52356021 | H3: =((Table1[[#This Row],[Prom. Nodos salvados óptimo IQCP]]-Table1[[#This Row],[Prom. Nodos salvados Rollout k=2]])/Table1[[#This Row],[Prom. Nodos salvados óptimo IQCP]])*100 -> 0.52356021 | I3: =((Table1[[#This Row],[Prom. Nodos salvados óptimo IQCP]]-Table1[[#This Row],[Prom. Nodos salvados Rollout k=3]])/Table1[[#This Row],[Prom. Nodos salvados óptimo IQCP]])*100 -> 0.52356021 | J3: =AVERAGEIF(Table2[n_nodes],Table1[[#This Row],[Nodos]],Table2[optimal_greedy]) -> 18.1
A4: 40 | B4: =COUNTIF(compare_results_1_nodes!B:B,comparaciones!A4) -> 10 | C4: =AVERAGEIF(Table2[n_nodes],Table1[[#This Row],[Nodos]],Table2[optimal_iqcp]) -> 36.3 | D4: =AVERAGEIF(Table2[n_nodes],Table1[[#This Row],[Nodos]],Table2[optimal_rollout k=1]) -> 35.4 | E4: =AVERAGEIF(Table2[n_nodes],Table1[[#This Row],[Nodos]],Table2[optimal_rollout k=2]) -> 36.3 | F4: =AVERAGEIF(Table2[n_nodes],Table1[[#This Row],[Nodos]],Table2[optimal_rollout k=3]) -> 36.3 | G4: =((Table1[[#This Row],[Prom. Nodos salvados óptimo IQCP]]-Table1[[#This Row],[Prom. Nodos salvados Rollout k=1]])/Table1[[#This Row],[Prom. Nodos salvados óptimo IQCP]])*100 -> 2.4793388 | H4: =((Table1[[#This Row],[Prom. Nodos salvados óptimo IQCP]]-Table1[[#This Row],[Prom. Nodos salvados Rollout k=2]])/Table1[[#This Row],[Prom. Nodos salvados óptimo IQCP]])*100 -> 0 | I4: =((Table1[[#This Row],[Prom. Nodos salvados óptimo IQCP]]-Table1[[#This Row],[Prom. Nodos salvados Rollout k=3]])/Table1[[#This Row],[Prom. Nodos salvados óptimo IQCP]])*100 -> 0 | J4: =AVERAGEIF(Table2[n_nodes],Table1[[#This Row],[Nodos]],Table2[optimal_greedy]) -> 35.6
A5: 50 | B5: =COUNTIF(compare_results_1_nodes!B:B,comparaciones!A5) -> 10 | C5: =AVERAGEIF(Table2[n_nodes],Table1[[#This Row],[Nodos]],Table2[optimal_iqcp]) -> 46.4 | D5: =AVERAGEIF(Table2[n_nodes],Table1[[#This Row],[Nodos]],Table2[optimal_rollout k=1]) -> 46.1 | E5: =AVERAGEIF(Table2[n_nodes],Table1[[#This Row],[Nodos]],Table2[optimal_rollout k=2]) -> 46.3 | F5: =AVERAGEIF(Table2[n_nodes],Table1[[#This Row],[Nodos]],Table2[optimal_rollout k=3]) -> 46.4 | G5: =((Table1[[#This Row],[Prom. Nodos salvados óptimo IQCP]]-Table1[[#This Row],[Prom. Nodos salvados Rollout k=1]])/Table1[[#This Row],[Prom. Nodos salvados óptimo IQCP]])*100 -> 0.64655172 | H5: =((Table1[[#This Row],[Prom. Nodos salvados óptimo IQCP]]-Table1[[#This Row],[Prom. Nodos salvados Rollout k=2]])/Table1[[#This Row],[Prom. Nodos salvados óptimo IQCP]])*100 -> 0.21551724 | I5: =((Table1[[#This Row],[Prom. Nodos salvados óptimo IQCP]]-Table1[[#This Row],[Prom. Nodos salvados Rollout k=3]])/Table1[[#This Row],[Prom. Nodos salvados óptimo IQCP]])*100 -> 0 | J5: =AVERAGEIF(Table2[n_nodes],Table1[[#This Row],[Nodos]],Table2[optimal_greedy]) -> 45.6
A6: 75 | B6: =COUNTIF(compare_results_1_nodes!B:B,comparaciones!A6) -> 10 | C6: =AVERAGEIF(Table2[n_nodes],Table1[[#This Row],[Nodos]],Table2[optimal_iqcp]) -> 70.4 | D6: =AVERAGEIF(Table2[n_nodes],Table1[[#This Row],[Nodos]],Table2[optimal_rollout k=1]) -> 67.9 | E6: =AVERAGEIF(Table2[n_nodes],Table1[[#This Row],[Nodos]],Table2[optimal_rollout k=2]) -> 70.2 | F6: =AVERAGEIF(Table2[n_nodes],Table1[[#This Row],[Nodos]],Table2[optimal_rollout k=3]) -> 70.3 | G6: =((Table1[[#This Row],[Prom. Nodos salvados óptimo IQCP]]-Table1[[#This Row],[Prom. Nodos salvados Rollout k=1]])/Table1[[#This Row],[Prom. Nodos salvados óptimo IQCP]])*100 -> 3.5511364 | H6: =((Table1[[#This Row],[Prom. Nodos salvados óptimo IQCP]]-Table1[[#This Row],[Prom. Nodos salvados Rollout k=2]])/Table1[[#This Row],[Prom. Nodos salvados óptimo IQCP]])*100 -> 0.28409091 | I6: =((Table1[[#This Row],[Prom. Nodos salvados óptimo IQCP]]-Table1[[#This Row],[Prom. Nodos salvados Rollout k=3]])/Table1[[#This Row],[Prom. Nodos salvados óptimo IQCP]])*100 -> 0.14204545 | J6: =AVERAGEIF(Table2[n_nodes],Table1[[#This Row],[Nodos]],Table2[optimal_greedy]) -> 68.4
A7: 100 | B7: =COUNTIF(compare_results_1_nodes!B:B,comparaciones!A7) -> 10 | C7: =AVERAGEIF(Table2[n_nodes],Table1[[#This Row],[Nodos]],Table2[optimal_iqcp]) -> 95.9 | D7: =AVERAGEIF(Table2[n_nodes],Table1[[#This Row],[Nodos]],Table2[optimal_rollout k=1]) -> 95.8 | E7: =AVERAGEIF(Table2[n_nodes],Table1[[#This Row],[Nodos]],Table2[optimal_rollout k=2]) -> 95.8 | F7: =AVERAGEIF(Table2[n_nodes],Table1[[#This Row],[Nodos]],Table2[optimal_rollout k=3]) -> 95.9 | G7: =((Table1[[#This Row],[Prom. Nodos salvados óptimo IQCP]]-Table1[[#This Row],[Prom. Nodos salvados Rollout k=1]])/Table1[[#This Row],[Prom. Nodos salvados óptimo IQCP]])*100 -> 0.10427529 | H7: =((Table1[[#This Row],[Prom. Nodos salvados óptimo IQCP]]-Table1[[#This Row],[Prom. Nodos salvados Rollout k=2]])/Table1[[#This Row],[Prom. Nodos salvados óptimo IQCP]])*100 -> 0.10427529 | I7: =((Table1[[#This Row],[Prom. Nodos salvados óptimo IQCP]]-Table1[[#This Row],[Prom. Nodos salvados Rollout k=3]])/Table1[[#This Row],[Prom. Nodos salvados óptimo IQCP]])*100 -> 0 | J7: =AVERAGEIF(Table2[n_nodes],Table1[[#This Row],[Nodos]],Table2[optimal_greedy]) -> 94.6
A12: Nodos | B12: Instancias | C12: Prom. T-CPU MIQCP | D12: Prom. T-CPU IQCP | E12: Prom. T-CPU ILP | F12: Prom. T-CPU Rollout k=1 | G12: Prom. T-CPU Rollout k=2 | H12: Prom. T-CPU Rollout k=3 | I12: Prom. T-CPU Greedy
A13: 20 | B13: =COUNTIF(Table2[n_nodes],Table3[[#This Row],[Nodos]]) -> 10 | C13: =AVERAGEIF(Table2[n_nodes],Table3[[#This Row],[Nodos]],Table2[duration_miqcp]) -> 37825.712 | D13: =AVERAGEIF(Table2[n_nodes],Table3[[#This Row],[Nodos]],Table2[duration_iqcp]) -> 4.7960814 | E13: =AVERAGEIF(Table2[n_nodes],Table3[[#This Row],[Nodos]],Table2[duration_ilp]) -> 11.439051 | F13: =AVERAGEIF(Table2[n_nodes],Table3[[#This Row],[Nodos]],Table2[time_taken k=1]) -> 0.042798654 | G13: =AVERAGEIF(Table2[n_nodes],Table3[[#This Row],[Nodos]],Table2[time_taken k=2]) -> 0.064155938 | H13: =AVERAGEIF(Table2[n_nodes],Table3[[#This Row],[Nodos]],Table2[time_taken k=3]) -> 0.13367109 | I13: =AVERAGEIF(Table2[n_nodes],Table3[[#This Row],[Nodos]],Table2[duration_greedy]) -> 0.003666544
A14: 25 | B14: =COUNTIF(Table2[n_nodes],Table3[[#This Row],[Nodos]]) -> 10 | C14: =AVERAGEIF(Table2[n_nodes],Table3[[#This Row],[Nodos]],Table2[duration_miqcp]) -> 66611.988 | D14: =AVERAGEIF(Table2[n_nodes],Table3[[#This Row],[Nodos]],Table2[duration_iqcp]) -> 12.175679 | E14: =AVERAGEIF(Table2[n_nodes],Table3[[#This Row],[Nodos]],Table2[duration_ilp]) -> 32.275744 | F14: =AVERAGEIF(Table2[n_nodes],Table3[[#This Row],[Nodos]],Table2[time_taken k=1]) -> 0.049439 | G14: =AVERAGEIF(Table2[n_nodes],Table3[[#This Row],[Nodos]],Table2[time_taken k=2]) -> 0.11470058 | H14: =AVERAGEIF(Table2[n_nodes],Table3[[#This Row],[Nodos]],Table2[time_taken k=3]) -> 0.22956654 | I14: =AVERAGEIF(Table2[n_nodes],Table3[[#This Row],[Nodos]],Table2[duration_greedy]) -> 0.0053447962
A15: 40 | B15: =COUNTIF(Table2[n_nodes],Table3[[#This Row],[Nodos]]) -> 10 | C15: =AVERAGEIF(Table2[n_nodes],Table3[[#This Row],[Nodos]],Table2[duration_miqcp]) -> #DIV/0! | D15: =AVERAGEIF(Table2[n_nodes],Table3[[#This Row],[Nodos]],Table2[duration_iqcp]) -> 64.142056 | E15: =AVERAGEIF(Table2[n_nodes],Table3[[#This Row],[Nodos]],Table2[duration_ilp]) -> 210.2392 | F15: =AVERAGEIF(Table2[n_nodes],Table3[[#This Row],[Nodos]],Table2[time_taken k=1]) -> 0.13105902 | G15: =AVERAGEIF(Table2[n_nodes],Table3[[#This Row],[Nodos]],Table2[time_taken k=2]) -> 1.056476 | H15: =AVERAGEIF(Table2[n_nodes],Table3[[#This Row],[Nodos]],Table2[time_taken k=3]) -> 4.2931186 | I15: =AVERAGEIF(Table2[n_nodes],Table3[[#This Row],[Nodos]],Table2[duration_greedy]) -> 0.0049083471
A16: 50 | B16: =COUNTIF(Table2[n_nodes],Table3[[#This Row],[Nodos]]) -> 10 | C16: =AVERAGEIF(Table2[n_nodes],Table3[[#This Row],[Nodos]],Table2[duration_miqcp]) -> #DIV/0! | D16: =AVERAGEIF(Table2[n_nodes],Table3[[#This Row],[Nodos]],Table2[duration_iqcp]) -> 188.42847 | E16: =AVERAGEIF(Table2[n_nodes],Table3[[#This Row],[Nodos]],Table2[duration_ilp]) -> 752.25583 | F16: =AVERAGEIF(Table2[n_nodes],Table3[[#This Row],[Nodos]],Table2[time_taken k=1]) -> 0.26793605 | G16: =AVERAGEIF(Table2[n_nodes],Table3[[#This Row],[Nodos]],Table2[time_taken k=2]) -> 3.0893571 | H16: =AVERAGEIF(Table2[n_nodes],Table3[[#This Row],[Nodos]],Table2[time_taken k=3]) -> 13.213538 | I16: =AVERAGEIF(Table2[n_nodes],Table3[[#This Row],[Nodos]],Table2[duration_greedy]) -> 0.0057149649
A17: 75 | B17: =COUNTIF(Table2[n_nodes],Table3[[#This Row],[Nodos]]) -> 10 | C17: =AVERAGEIF(Table2[n_nodes],Table3[[#This Row],[Nodos]],Table2[duration_miqcp]) -> #DIV/0! | D17: =AVERAGEIF(Table2[n_nodes],Table3[[#This Row],[Nodos]],Table2[duration_iqcp]) -> 2021.6529 | E17: =AVERAGEIF(Table2[n_nodes],Table3[[#This Row],[Nodos]],Table2[duration_ilp]) -> 963.23044 | F17: =AVERAGEIF(Table2[n_nodes],Table3[[#This Row],[Nodos]],Table2[time_taken k=1]) -> 1.484024 | G17: =AVERAGEIF(Table2[n_nodes],Table3[[#This Row],[Nodos]],Table2[time_taken k=2]) -> 16.21411 | H17: =AVERAGEIF(Table2[n_nodes],Table3[[#This Row],[Nodos]],Table2[time_taken k=3]) -> 98.137982 | I17: =AVERAGEIF(Table2[n_nodes],Table3[[#This Row],[Nodos]],Table2[duration_greedy]) -> 0.0072853565
A18: 100 | B18: =COUNTIF(Table2[n_nodes],Table3[[#This Row],[Nodos]]) -> 10 | C18: =AVERAGEIF(Table2[n_nodes],Table3[[#This Row],[Nodos]],Table2[duration_miqcp]) -> #DIV/0! | D18: =AVERAGEIF(Table2[n_nodes],Table3[[#This Row],[Nodos]],Table2[duration_iqcp]) -> 3171.4132 | E18: =AVERAGEIF(Table2[n_nodes],Table3[[#This Row],[Nodos]],Table2[duration_ilp]) -> 3318.0467 | F18: =AVERAGEIF(Table2[n_nodes],Table3[[#This Row],[Nodos]],Table2[time_taken k=1]) -> 2.1543052 | G18: =AVERAGEIF(Table2[n_nodes],Table3[[#This Row],[Nodos]],Table2[time_taken k=2]) -> 55.666941 | H18: =AVERAGEIF(Table2[n_nodes],Table3[[#This Row],[Nodos]],Table2[time_taken k=3]) -> 384.89191 | I18: =AVERAGEIF(Table2[n_nodes],Table3[[#This Row],[Nodos]],Table2[duration_greedy]) -> 0.0089655399

Sheet compare_nodes
A1: id | B1: n_nodes | C1: dp | D1: iqcp | E1: ilp | F1: miqcp | G1: greedy | H1: rollout k=1 | I1: rollout k=2 | J1: rollout k=3
A2: 1 | B2: 25 | C2: 16 | D2: 16 | E2: 16 | F2: 16 | G2: 16 | H2: 16 | I2: 16 | J2: 16
A3: 2 | B3: 25 | C3: 20 | D3: 20 | E3: 20 | G3: 19 | H3: 20 | I3: 20 | J3: 20
A4: 3 | B4: 25 | C4: 21 | D4: 21 | E4: 21 | F4: 21 | G4: 21 | H4: 21 | I4: 21 | J4: 21
A5: 4 | B5: 25 | C5: 18 | D5: 18 | E5: 18 | F5: 18 | G5: 17 | H5: 17 | I5: 17 | J5: 17
A6: 5 | B6: 25 | C6: 22 | D6: 22 | E6: 22 | F6: 22 | G6: 22 | H6: 22 | I6: 22 | J6: 22
A7: 6 | B7: 25 | C7: 19 | D7: 19 | E7: 19 | G7: 19 | H7: 19 | I7: 19 | J7: 19
A8: 7 | B8: 25 | C8: 18 | D8: 18 | E8: 18 | G8: 18 | H8: 18 | I8: 18 | J8: 18
A9: 8 | B9: 25 | C9: 19 | D9: 19 | E9: 19 | G9: 19 | H9: 19 | I9: 19 | J9: 19
A10: 9 | B10: 25 | C10: 18 | D10: 18 | E10: 18 | G10: 18 | H10: 18 | I10: 18 | J10: 18
A11: 10 | B11: 25 | C11: 20 | D11: 20 | E11: 20 | G11: 12 | H11: 20 | I11: 20 | J11: 20
A12: 11 | B12: 40 | C12: 36 | D12: 36 | E12: 36 | G12: 31 | H12: 36 | I12: 36 | J12: 36
A13: 12 | B13: 40 | C13: 36 | D13: 36 | E13: 36 | G13: 36 | H13: 36 | I13: 36 | J13: 36
A14: 13 | B14: 40 | D14: 38 | E14: 38 | G14: 38 | H14: 38 | I14: 38 | J14: 38
A15: 14 | B15: 40 | C15: 39 | D15: 39 | E15: 39 | G15: 39 | H15: 39 | I15: 39 | J15: 39
A16: 15 | B16: 40 | C16: 36 | D16: 36 | E16: 36 | G16: 36 | H16: 36 | I16: 36 | J16: 36
A17: 16 | B17: 40 | C17: 34 | D17: 34 | E17: 34 | G17: 33 | H17: 26 | I17: 34 | J17: 34
A18: 17 | B18: 40 | C18: 36 | D18: 36 | E18: 36 | G18: 35 | H18: 35 | I18: 36 | J18: 36
A19: 18 | B19: 40 | C19: 38 | D19: 38 | E19: 38 | G19: 38 | H19: 38 | I19: 38 | J19: 38
A20: 19 | B20: 40 | C20: 34 | D20: 34 | E20: 34 | G20: 34 | H20: 34 | I20: 34 | J20: 34
A21: 20 | B21: 40 | D21: 36 | E21: 36 | G21: 36 | H21: 36 | I21: 36 | J21: 36
A22: 21 | B22: 50 | D22: 46 | E22: 46 | G22: 46 | H22: 46 | I22: 46 | J22: 46
A23: 22 | B23: 50 | D23: 49 | E23: 49 | G23: 48 | H23: 49 | I23: 49 | J23: 49
A24: 23 | B24: 50 | D24: 48 | E24: 48 | G24: 47 | H24: 47 | I24: 48 | J24: 48
A25: 24 | B25: 50 | D25: 48 | E25: 48 | G25: 46 | H25: 48 | I25: 48 | J25: 48
A26: 25 | B26: 50 | D26: 44 | E26: 44 | G26: 42 | H26: 43 | I26: 44 | J26: 44
A27: 26 | B27: 50 | D27: 45 | E27: 45 | G27: 44 | H27: 45 | I27: 45 | J27: 45
A28: 27 | B28: 50 | D28: 46 | E28: 46 | G28: 46 | H28: 46 | I28: 46 | J28: 46
A29: 28 | B29: 50 | D29: 47 | E29: 47 | G29: 46 | H29: 46 | I29: 46 | J29: 47
A30: 29 | B30: 50 | D30: 47 | E30: 47 | G30: 47 | H30: 47 | I30: 47 | J30: 47
A31: 30 | B31: 50 | D31: 44 | E31: 44 | G31: 44 | H31: 44 | I31: 44 | J31: 44
A32: 31 | B32: 75 | D32: 71 | G32: 71 | H32: 71 | I32: 71 | J32: 71
A33: 32 | B33: 75 | D33: 71 | G33: 71 | H33: 71 | I33: 71 | J33: 71
A34: 33 | B34: 75 | D34: 72 | G34: 71 | H34: 72 | I34: 72 | J34: 72
A35: 34 | B35: 75 | D35: 74 | G35: 74 | H35: 74 | I35: 74 | J35: 74
A36: 35 | B36: 75 | D36: 71 | G36: 71 | H36: 71 | I36: 71 | J36: 71
A37: 36 | B37: 75 | D37: 65 | G37: 59 | H37: 64 | I37: 64 | J37: 65
A38: 37 | B38: 75 | D38: 69 | G38: 65 | H38: 69 | I38: 69 | J38: 69
A39: 38 | B39: 75 | D39: 73 | G39: 72 | H39: 59 | I39: 73 | J39: 73
A40: 39 | B40: 75 | D40: 69 | G40: 68 | H40: 64 | I40: 69 | J40: 69
...

Sheet compare_times
A1: id | B1: n_nodes | C1: duration_dp | D1: duration_iqcp | E1: duration_ilp | F1: duration_miqcp | G1: duration_greedy | H1: duration_rollout k=1 | I1: duration_rollout k=2 | J1: duration_rollout k=3
A2: 1 | B2: 25 | C2: 0.17613745 | D2: 13.040887 | E2: 47.843506 | F2: 23232.208 | G2: 0.014831305 | H2: 0.063491875 | I2: 0.14683254 | J2: 0.29684417
A3: 2 | B3: 25 | C3: 0.15577698 | D3: 5.0183191 | E3: 17.926093 | F3: 86400.072 | G3: 0.004509449 | H3: 0.053255167 | I3: 0.17472088 | J3: 0.24558804
A4: 3 | B4: 25 | C4: 3.4204645 | D4: 10.010939 | E4: 17.00809 | F4: 1425.4224 | G4: 0.0040242672 | H4: 0.027863166 | I4: 0.10382533 | J4: 0.26194842
A5: 4 | B5: 25 | C5: 0.35159588 | D5: 8.5404961 | E5: 27.014186 | F5: 79622.902 | G5: 0.0041053295 | H5: 0.051364458 | I5: 0.051264959 | J5: 0.15143442
A6: 5 | B6: 25 | C6: 1.7921865 | D6: 10.067082 | E6: 20.000447 | F6: 43438.653 | G6: 0.0041453838 | H6: 0.020007292 | I6: 0.12626475 | J6: 0.18059608
A7: 6 | B7: 25 | C7: 0.19284844 | D7: 10.538142 | E7: 37.179535 | F7: 86400.036 | G7: 0.0046305656 | H7: 0.049223333 | I7: 0.10428475 | J7: 0.19400329
A8: 7 | B8: 25 | C8: 2.0427024 | D8: 13.685847 | E8: 43.679956 | F8: 86400.141 | G8: 0.004298687 | H8: 0.055771708 | I8: 0.11870592 | J8: 0.29773333
A9: 8 | B9: 25 | C9: 1.8801317 | D9: 15.032512 | E9: 35.265093 | F9: 86400.196 | G9: 0.0043210983 | H9: 0.05192225 | I9: 0.10405258 | J9: 0.30845104
A10: 9 | B10: 25 | C10: 0.31319165 | D10: 27.342374 | E10: 46.145465 | F10: 86400.132 | G10: 0.0044243336 | H10: 0.056644583 | I10: 0.093496291 | J10: 0.1689675
A11: 10 | B11: 25 | C11: 0.11955214 | D11: 8.4801874 | E11: 30.69507 | F11: 86400.117 | G11: 0.0041575432 | H11: 0.064846167 | I11: 0.12355775 | J11: 0.19009912
A12: 11 | B12: 40 | C12: 756.5457 | D12: 78.926251 | E12: 336.39173 | G12: 0.0050559044 | H12: 0.16860275 | I12: 0.82291654 | J12: 2.4259862
A13: 12 | B13: 40 | C13: 10313.59 | D13: 57.669784 | E13: 124.70194 | G13: 0.0047380924 | H13: 0.10331875 | I13: 1.5188525 | J13: 4.3989879
A14: 13 | B14: 40 | C14: 86400.276 | D14: 92.590263 | E14: 196.18166 | G14: 0.0048034191 | H14: 0.13974788 | I14: 0.97011229 | J14: 8.9091197
A15: 14 | B15: 40 | C15: 2821.6056 | D15: 49.555662 | E15: 110.5152 | G15: 0.0050327778 | H15: 0.074470166 | I15: 0.8872295 | J15: 4.984186
A16: 15 | B16: 40 | C16: 19938.966 | D16: 68.489383 | E16: 240.73659 | G16: 0.0049045086 | H16: 0.088303416 | I16: 0.81283458 | J16: 1.835798
A17: 16 | B17: 40 | C17: 430.32573 | D17: 58.67364 | E17: 262.88486 | G17: 0.0048835278 | H17: 0.20691229 | I17: 1.182434 | J17: 3.3875301
A18: 17 | B18: 40 | C18: 3930.6082 | D18: 58.510286 | E18: 241.10887 | G18: 0.0047316551 | H18: 0.11658729 | I18: 1.0260741 | J18: 2.1229899
A19: 18 | B19: 40 | C19: 3804.9753 | D19: 57.792312 | E19: 132.33697 | G19: 0.0053415298 | H19: 0.11625504 | I19: 0.87141317 | J19: 3.1248001
A20: 19 | B20: 40 | C20: 4533.9694 | D20: 43.429265 | E20: 184.54431 | G20: 0.0047674179 | H20: 0.09374025 | I20: 0.79964346 | J20: 3.6631603
A21: 20 | B21: 40 | C21: 86402.943 | D21: 75.783719 | E21: 272.98981 | G21: 0.0048246384 | H21: 0.20265233 | I21: 1.67325 | J21: 8.0786281
A22: 21 | B22: 50 | D22: 148.4857 | E22: 742.77179 | G22: 0.0053641796 | H22: 0.16531675 | I22: 2.4920138 | J22: 18.430154
A23: 22 | B23: 50 | D23: 68.101652 | E23: 188.78203 | G23: 0.005525589 | H23: 0.40008525 | I23: 4.7785656 | J23: 13.621834
A24: 23 | B24: 50 | D24: 163.80629 | E24: 625.07527 | G24: 0.0056612492 | H24: 0.33562788 | I24: 3.2808888 | J24: 20.098683
A25: 24 | B25: 50 | D25: 132.75861 | E25: 429.64812 | G25: 0.0060706139 | H25: 0.38118025 | I25: 2.7484046 | J25: 18.026117
A26: 25 | B26: 50 | D26: 671.9996 | E26: 2373.3998 | G26: 0.0057797432 | H26: 0.19379846 | I26: 2.4769078 | J26: 13.380208
A27: 26 | B27: 50 | D27: 130.10778 | E27: 602.71775 | G27: 0.0056357384 | H27: 0.28343675 | I27: 4.3689845 | J27: 15.811426
A28: 27 | B28: 50 | D28: 163.08274 | E28: 833.21768 | G28: 0.005720377 | H28: 0.15869842 | I28: 1.9241331 | J28: 4.0078034
A29: 28 | B29: 50 | D29: 133.62735 | E29: 517.27749 | G29: 0.0057938099 | H29: 0.25469179 | I29: 2.8002696 | J29: 7.0354148
A30: 29 | B30: 50 | C30: 86400.255 | D30: 116.93431 | E30: 448.17442 | G30: 0.0055742264 | H30: 0.30268154 | I30: 3.9741486 | J30: 14.789427
A31: 30 | B31: 50 | C31: 86400.26 | D31: 155.38067 | E31: 761.49398 | G31: 0.0060241222 | H31: 0.20384346 | I31: 2.0492545 | J31: 6.9343138
A32: 31 | B32: 75 | D32: 636.5103 | E32: 829.76647 | G32: 0.0072510242 | H32: 0.85136942 | I32: 13.028707 | J32: 56.52815
A33: 32 | B33: 75 | D33: 801.98344 | E33: 990.50533 | G33: 0.0071249008 | H33: 0.52399946 | I33: 18.090029 | J33: 96.128
A34: 33 | B34: 75 | D34: 862.76423 | E34: 1056.4615 | G34: 0.0074980259 | H34: 0.82913062 | I34: 25.060403 | J34: 177.60295
A35: 34 | B35: 75 | D35: 797.57794 | E35: 997.39091 | G35: 0.0074398518 | H35: 0.43395963 | I35: 13.930747 | J35: 85.405976
A36: 35 | B36: 75 | D36: 737.52451 | E36: 947.69314 | G36: 0.0074191093 | H36: 0.737749 | I36: 18.773502 | J36: 70.043701
A37: 36 | B37: 75 | D37: 12748.104 | E37: 1018.6011 | G37: 0.0076315403 | H37: 0.48733279 | I37: 3.9797428 | J37: 21.245699
A38: 37 | B38: 75 | D38: 859.7922 | E38: 1054.3818 | G38: 0.0069537163 | H38: 1.9745873 | I38: 25.696464 | J38: 159.59677
A39: 38 | B39: 75 | D39: 966.47409 | E39: 1181.814 | G39: 0.0067458153 | H39: 7.0090071 | I39: 30.645577 | J39: 236.93741
A40: 39 | B40: 75 | D40: 499.4171 | E40: 660.48237 | G40: 0.0071530342 | H40: 0.74755229 | I40: 6.8716945 | J40: 37.626908
...

Sheet compare_solutions
A1: id | B1: solution_iqcp | C1: solution_rollout k=1 | D1: solution_rollout k=2 | E1: solution_rollout k=3
A2: 1 | B2: [-1, 2, 3] | C2: [23, 2, 21, 19] | D2: [23, 2, 21, 19] | E2: [14, 3, 1]
A3: 2 | B3: [-1, 18, 21, 19] | C3: [18, 21, 19] | D3: [18, 21, 19] | E3: [18, 21, 19]
A4: 3 | B4: [-1, 10] | C4: [10] | D4: [10] | E4: [10]
A5: 4 | B5: [-1, 11, 5, 2, 4] | C5: [1, 16, 23] | D5: [1, 16, 23] | E5: [1, 16, 23]
A6: 5 | B6: [-1, 8] | C6: [8] | D6: [8] | E6: [8]
A7: 6 | B7: [-1, 0, 2, 17] | C7: [0, 2, 17] | D7: [0, 2, 17] | E7: [0, 2, 17]
A8: 7 | B8: [-1, 7, 10, 8, 9] | C8: [7, 10, 8, 9] | D8: [7, 10, 8, 9] | E8: [7, 10, 8, 9]
A9: 8 | B9: [-1, 4, 17, 13] | C9: [4, 17, 13] | D9: [4, 17, 13] | E9: [4, 17, 13]
A10: 9 | B10: [-1, 6, 24, 15, 23] | C10: [6, 24, 15, 23] | D10: [6, 24, 15, 23] | E10: [6, 24, 15, 23]
A11: 10 | B11: [-1, 15, 13, 5, 17] | C11: [15, 12, 11, 22] | D11: [15, 12, 11, 22] | E11: [15, 12, 11, 22]
A12: 11 | B12: [-1, 38, 26, 11, 15, 8, 7] | C12: [38, 32, 33, 8, 7] | D12: [38, 32, 33, 8, 7] | E12: [38, 32, 33, 8, 7]
A13: 12 | B13: [-1, 34] | C13: [34] | D13: [34] | E13: [34]
... A61: 60 | B61: [-1, 4, 1] | C61: [4, 1] | D61: [4, 1] | E61: [4, 1]

Sheet Sheet1
A1: ID | B1: Nodos | C1: Duración IQCP | D1: ÓPTIMO | E1: Duración Rollout k=1 | F1: Rollout k=1 | G1: Duración Rollout k=2 | H1: Rollout k=2
A2: 38 | B2: 75 | C2: 966.47409 | D2: 73 | E2: 7.0090071 | F2: 59 | G2: 30.645577 | H2: 73
A3: 5 | B3: 25 | C3: 10.067082 | D3: 22 | E3: 0.020007292 | F3: 22 | G3: 0.12626475 | H3: 22

Sheet fortimes
A1: experiment | B1: n_nodes | C1: duration_greedy | D1: time_taken k=1 | E1: time_taken k=2 | F1: time_taken k=3
A2: 52 | B2: 20 | C2: 0.0037240982 | D2: 0.0578075 | E2: 0.09065975 | F2: 0.16066162
A3: 53 | B3: 20 | C3: 0.0036454201 | D3: 0.039888125 | E3: 0.05805 | F3: 0.088539542
A4: 60 | B4: 20 | C4: 0.0038189888 | D4: 0.028228875 | E4: 0.053727833 | F4: 0.093913084
A5: 54 | B5: 20 | C5: 0.0035321712 | D5: 0.028433917 | E5: 0.054628792 | F5: 0.08802725
A6: 58 | B6: 20 | C6: 0.0035631657 | D6: 0.044324792 | E6: 0.067796667 | F6: 0.154934
A7: 57 | B7: 20 | C7: 0.0035440922 | D7: 0.048121416 | E7: 0.059643625 | F7: 0.24887813
A8: 56 | B8: 20 | C8: 0.0034809113 | D8: 0.055611166 | E8: 0.073612583 | F8: 0.11371067
A9: 59 | B9: 20 | C9: 0.0034942627 | D9: 0.015046584 | E9: 0.071703583 | F9: 0.18527125
A10: 51 | B10: 20 | C10: 0.0042831898 | D10: 0.044080167 | E10: 0.070189584 | F10: 0.10280867
A11: 55 | B11: 20 | C11: 0.0035791397 | D11: 0.066444 | E11: 0.041546959 | F11: 0.099966667
A12: 10 | B12: 25 | C12: 0.0041575432 | D12: 0.064846167 | E12: 0.12355775 | F12: 0.19009912
A13: 2 | B13: 25 | C13: 0.004509449 | D13: 0.053255167 | E13: 0.17472088 | F13: 0.24558804
... A61: 46 | B61: 100 | C61: 0.0089771748 | D61: 1.8844508 | E61: 33.318394 | F61: 142.23311

Sheet timegreedy
A1: 20 | B1: 25 | C1: 40 | D1: 50 | E1: 75 | F1: 100
A2: 0.0037240982 | B2: 0.0041575432 | C2: 0.0050559044 | D2: 0.0060706139 | E2: 0.0069537163 | F2: 0.0090699196
A3: 0.0036454201 | B3: 0.004509449 | C3: 0.0050327778 | D3: 0.0056357384 | E3: 0.0074980259 | F3: 0.0094974041
A4: 0.0038189888 | B4: 0.0041453838 | C4: 0.0049045086 | D4: 0.005525589 | E4: 0.0074398518 | F4: 0.009118557
A5: 0.0035321712 | B5: 0.0040242672 | C5: 0.0047674179 | D5: 0.005720377 | E5: 0.0071249008 | F5: 0.0086023808
A6: 0.0035631657 | B6: 0.0046305656 | C6: 0.0047380924 | D6: 0.0053641796 | E6: 0.0074191093 | F6: 0.0089905262
A7: 0.0035440922 | B7: 0.0043210983 | C7: 0.0053415298 | D7: 0.0060241222 | E7: 0.0072510242 | F7: 0.0088615417
A8: 0.0034809113 | B8: 0.004298687 | C8: 0.0048034191 | D8: 0.0055742264 | E8: 0.0076315403 | F8: 0.0088996887
A9: 0.0034942627 | B9: 0.0044243336 | C9: 0.0048246384 | D9: 0.0057797432 | E9: 0.0076365471 | F9: 0.0087280273
A10: 0.0042831898 | B10: 0.014831305 | C10: 0.0047316551 | D10: 0.0057938099 | E10: 0.0071530342 | F10: 0.0089101791
A11: 0.0035791397 | B11: 0.0041053295 | C11: 0.0048835278 | D11: 0.0056612492 | E11: 0.0067458153 | F11: 0.0089771748

Sheet time1
A1: 20 | B1: 25 | C1: 40 | D1: 50 | E1: 75 | F1: 100
A2: 0.0578075 | B2: 0.064846167 | C2: 0.16860275 | D2: 0.38118025 | E2: 1.9745873 | F2: 1.235143
A3: 0.039888125 | B3: 0.053255167 | C3: 0.074470166 | D3: 0.28343675 | E3: 0.82913062 | F3: 1.242258
A4: 0.028228875 | B4: 0.020007292 | C4: 0.088303416 | D4: 0.40008525 | E4: 0.43395963 | F4: 4.4783545
A5: 0.028433917 | B5: 0.027863166 | C5: 0.09374025 | D5: 0.15869842 | E5: 0.52399946 | F5: 1.677113
A6: 0.044324792 | B6: 0.049223333 | C6: 0.10331875 | D6: 0.16531675 | E6: 0.737749 | F6: 2.6676563
A7: 0.048121416 | B7: 0.05192225 | C7: 0.11625504 | D7: 0.20384346 | E7: 0.85136942 | F7: 2.9854539
A8: 0.055611166 | B8: 0.055771708 | C8: 0.13974788 | D8: 0.30268154 | E8: 0.48733279 | F8: 1.1968655
A9: 0.015046584 | B9: 0.056644583 | C9: 0.20265233 | D9: 0.19379846 | E9: 1.2455522 | F9: 1.5175213
A10: 0.044080167 | B10: 0.063491875 | C10: 0.11658729 | D10: 0.25469179 | E10: 0.74755229 | F10: 2.6582356
A11: 0.066444 | B11: 0.051364458 | C11: 0.20691229 | D11: 0.33562788 | E11: 7.0090071 | F11: 1.8844508

Sheet time2
A1: 20 | B1: 25 | C1: 40 | D1: 50 | E1: 75 | F1: 100
A2: 0.09065975 | B2: 0.12355775 | C2: 0.82291654 | D2: 2.7484046 | E2: 25.696464 | F2: 3.3276985
A3: 0.05805 | B3: 0.17472088 | C3: 0.8872295 | D3: 4.3689845 | E3: 25.060403 | F3: 43.969725
A4: 0.053727833 | B4: 0.12626475 | C4: 0.81283458 | D4: 4.7785656 | E4: 13.930747 | F4: 105.60224
A5: 0.054628792 | B5: 0.10382533 | C5: 0.79964346 | D5: 1.9241331 | E5: 18.090029 | F5: 69.539149
A6: 0.067796667 | B6: 0.10428475 | C6: 1.5188525 | D6: 2.4920138 | E6: 18.773502 | F6: 95.267819
A7: 0.059643625 | B7: 0.10405258 | C7: 0.87141317 | D7: 2.0492545 | E7: 13.028707 | F7: 44.019742
A8: 0.073612583 | B8: 0.11870592 | C8: 0.97011229 | D8: 3.9741486 | E8: 3.9797428 | F8: 55.732547
A9: 0.071703583 | B9: 0.093496291 | C9: 1.67325 | D9: 2.4769078 | E9: 6.0642318 | F9: 28.185838
A10: 0.070189584 | B10: 0.14683254 | C10: 1.0260741 | D10: 2.8002696 | E10: 6.8716945 | F10: 77.706257
A11: 0.041546959 | B11: 0.051264959 | C11: 1.182434 | D11: 3.2808888 | E11: 30.645577 | F11: 33.318394

Sheet time3
A1: 20 | B1: 25 | C1: 40 | D1: 50 | E1: 75 | F1: 100
A2: 0.16066162 | B2: 0.19009912 | C2: 2.4259862 | D2: 18.026117 | E2: 159.59677 | F2: 87.265396
A3: 0.088539542 | B3: 0.24558804 | C3: 4.984186 | D3: 15.811426 | E3: 177.60295 | F3: 156.99346
A4: 0.093913084 | B4: 0.18059608 | C4: 1.835798 | D4: 13.621834 | E4: 85.405976 | F4: 899.17825
A5: 0.08802725 | B5: 0.26194842 | C5: 3.6631603 | D5: 4.0078034 | E5: 96.128 | F5: 681.20098
A6: 0.154934 | B6: 0.19400329 | C6: 4.3989879 | D6: 18.430154 | E6: 70.043701 | F6: 331.37684
A7: 0.24887813 | B7: 0.30845104 | C7: 3.1248001 | D7: 6.9343138 | E7: 56.52815 | F7: 549.05003
A8: 0.11371067 | B8: 0.29773333 | C8: 8.9091197 | D8: 14.789427 | E8: 21.245699 | F8: 367.49206
A9: 0.18527125 | B9: 0.1689675 | C9: 8.0786281 | D9: 13.380208 | E9: 40.26426 | F9: 203.3715
A10: 0.10280867 | B10: 0.29684417 | C10: 2.1229899 | D10: 7.0354148 | E10: 37.626908 | F10: 430.75752
A11: 0.099966667 | B11: 0.15143442 | C11: 3.3875301 | D11: 20.098683 | E11: 236.93741 | F11: 142.23311
