Workbook

Sheet compare_results_1_nodes
A1: experiment | B1: duration_dp | C1: solution_dp | D1: optimal_dp | E1: duration_iqcp | F1: solution_iqcp | G1: optimal_iqcp | H1: duration | I1: solution | J1: optimal | K1: duration_miqcp | L1: solution_miqcp | M1: optimal_miqcp | N1: duration_greedy | O1: solution_greedy | P1: optimal_greedy | Q1: n_nodes | R1: solution_rollout | S1: final_damage | T1: time_taken | U1: optimal_rollout | V1: diff_iqcp_rollout | W1: diff_ilp_rollout | X1: diff_greedy_rollout
A2: 1 | B2: 0.17613745 | C2: [-1, 2, 3] | D2: 16 | E2: 13.040887 | F2: [-1, 2, 3] | G2: 16 | H2: 47.843506 | I2: [-1, 2, 23, 19, 21] | J2: 16 | K2: 23232.208 | L2: [-1, 14, 3, 1, 15, 4, 18, 24, 16, 6] | M2: 16 | N2: 0.014831305 | O2: [-1, 2, 3] | P2: 16 | Q2: 25 | R2: [23, 2, 21, 19] | S2: 9 | T2: 0.10971253 | U2: 16 | V2: 0 | W2: 0 | X2: 0
A3: 2 | B3: 0.15577698 | C3: [-1, 18, 19, 21] | D3: 20 | E3: 5.0183191 | F3: [-1, 18, 21, 19] | G3: 20 | H3: 17.926093 | I3: [-1, 18, 21, 19] | J3: 20 | K3: 86400.072 | N3: 0.004509449 | O3: [-1, 1, 6] | P3: 19 | Q3: 25 | R3: [18, 21, 19] | S3: 5 | T3: 0.11747764 | U3: 20 | V3: 0 | W3: 0 | X3: 1
A4: 3 | B4: 3.4204645 | C4: [-1, 10] | D4: 21 | E4: 10.010939 | F4: [-1, 10] | G4: 21 | H4: 17.00809 | I4: [-1, 10] | J4: 21 | K4: 1425.4224 | L4: [-1, 10] | M4: 21 | N4: 0.0040242672 | O4: [-1, 10] | P4: 21 | Q4: 25 | R4: [10] | S4: 4 | T4: 0.08475813 | U4: 21 | V4: 0 | W4: 0 | X4: 0
A5: 5 | B5: 1.7921865 | C5: [-1, 8] | D5: 22 | E5: 10.067082 | F5: [-1, 8] | G5: 22 | H5: 20.000447 | I5: [-1, 8] | J5: 22 | K5: 43438.653 | L5: [-1, 8, 24, 21, 20] | M5: 22 | N5: 0.0041453838 | O5: [-1, 8] | P5: 22 | Q5: 25 | R5: [8] | S5: 3 | T5: 0.063388106 | U5: 22 | V5: 0 | W5: 0 | X5: 0
A6: 6 | B6: 0.19284844 | C6: [-1, 0, 2, 17] | D6: 19 | E6: 10.538142 | F6: [-1, 0, 2, 17] | G6: 19 | H6: 37.179535 | I6: [-1, 0, 2, 17] | J6: 19 | K6: 86400.036 | N6: 0.0046305656 | O6: [-1, 0, 2, 17] | P6: 19 | Q6: 25 | R6: [0, 2, 17] | S6: 6 | T6: 0.065004193 | U6: 19 | V6: 0 | W6: 0 | X6: 0
A7: 7 | B7: 2.0427024 | C7: [-1, 1, 10, 4, 9, 8] | D7: 18 | E7: 13.685847 | F7: [-1, 7, 10, 8, 9] | G7: 18 | H7: 43.679956 | I7: [-1, 7, 10, 4, 8] | J7: 18 | K7: 86400.141 | N7: 0.004298687 | O7: [-1, 7, 24] | P7: 18 | Q7: 25 | R7: [7, 10, 8, 9] | S7: 7 | T7: 0.072989716 | U7: 18 | V7: 0 | W7: 0 | X7: 0
A8: 8 | B8: 1.8801317 | C8: [-1, 4, 9, 6, 11, 22] | D8: 19 | E8: 15.032512 | F8: [-1, 4, 17, 13] | G8: 19 | H8: 35.265093 | I8: [-1, 4, 17, 13] | J8: 19 | K8: 86400.196 | N8: 0.0043210983 | O8: [-1, 4, 17, 13] | P8: 19 | Q8: 25 | R8: [4, 17, 13] | S8: 6 | T8: 0.081918735 | U8: 19 | V8: 0 | W8: 0 | X8: 0
A9: 9 | B9: 0.31319165 | C9: [-1, 6, 0, 1, 22, 10, 18, 8, 9] | D9: 18 | E9: 27.342374 | F9: [-1, 6, 24, 15, 23] | G9: 18 | H9: 46.145465 | I9: [-1, 6, 24, 23, 15] | J9: 18 | K9: 86400.132 | N9: 0.0044243336 | O9: [-1, 6, 24, 23, 15] | P9: 18 | Q9: 25 | R9: [6, 24, 15, 23] | S9: 7 | T9: 0.082151051 | U9: 18 | V9: 0 | W9: 0 | X9: 0
A10: 10 | B10: 0.11955214 | C10: [-1, 15, 12, 11, 22] | D10: 20 | E10: 8.4801874 | F10: [-1, 15, 13, 5, 17] | G10: 20 | H10: 30.69507 | I10: [-1, 15, 13, 5, 17] | J10: 20 | K10: 86400.117 | N10: 0.0041575432 | O10: [-1, 13, 14, 3] | P10: 12 | Q10: 25 | R10: [15, 12, 11, 22] | S10: 5 | T10: 0.080581652 | U10: 20 | V10: 0 | W10: 0 | X10: 8
A11: 11 | B11: 756.5457 | C11: [-1, 38, 26, 11, 15, 7, 8] | D11: 36 | E11: 78.926251 | F11: [-1, 38, 26, 11, 15, 8, 7] | G11: 36 | H11: 336.39173 | I11: [-1, 38, 32, 33, 8, 7] | J11: 36 | N11: 0.0050559044 | O11: [-1, 26, 35, 4] | P11: 31 | Q11: 40 | R11: [38, 32, 33, 8, 7] | S11: 4 | T11: 0.50610813 | U11: 36 | V11: 0 | W11: 0 | X11: 5
A12: 12 | B12: 10313.59 | C12: [-1, 34] | D12: 36 | E12: 57.669784 | F12: [-1, 34] | G12: 36 | H12: 124.70194 | I12: [-1, 34] | J12: 36 | N12: 0.0047380924 | O12: [-1, 34] | P12: 36 | Q12: 40 | R12: [34] | S12: 4 | T12: 0.53833238 | U12: 36 | V12: 0 | W12: 0 | X12: 0
A13: 13 | B13: 86400.276 | E13: 92.590263 | F13: [-1, 7, 24] | G13: 38 | H13: 196.18166 | I13: [-1, 24, 7] | J13: 38 | N13: 0.0048034191 | O13: [-1, 24, 7] | P13: 38 | Q13: 40 | R13: [7, 24] | S13: 2 | T13: 0.60947378 | U13: 38 | V13: 0 | W13: 0 | X13: 0
A14: 14 | B14: 2821.6056 | C14: [-1, 13, 6, 12] | D14: 39 | E14: 49.555662 | F14: [-1, 13, 6, 12] | G14: 39 | H14: 110.5152 | I14: [-1, 13, 12, 6] | J14: 39 | N14: 0.0050327778 | O14: [-1, 13, 6, 12] | P14: 39 | Q14: 40 | R14: [13, 6, 12] | S14: 1 | T14: 0.25606458 | U14: 39 | V14: 0 | W14: 0 | X14: 0
A15: 15 | B15: 19938.966 | C15: [-1, 28, 7, 13] | D15: 36 | E15: 68.489383 | F15: [-1, 28, 7, 13] | G15: 36 | H15: 240.73659 | I15: [-1, 28, 7, 13] | J15: 36 | N15: 0.0049045086 | O15: [-1, 28, 7, 13] | P15: 36 | Q15: 40 | R15: [28, 13, 7] | S15: 4 | T15: 0.35657852 | U15: 36 | V15: 0 | W15: 0 | X15: 0
A16: 16 | B16: 430.32573 | C16: [-1, 3, 35, 28, 14] | D16: 34 | E16: 58.67364 | F16: [-1, 28, 3, 35, 14] | G16: 34 | H16: 262.88486 | I16: [-1, 28, 35, 3, 14] | J16: 34 | N16: 0.0048835278 | O16: [-1, 28, 13] | P16: 33 | Q16: 40 | R16: [3, 35, 28, 14] | S16: 6 | T16: 0.61351311 | U16: 34 | V16: 0 | W16: 0 | X16: 1
A17: 18 | B17: 3804.9753 | C17: [-1, 12, 9, 4, 23, 33] | D17: 38 | E17: 57.792312 | F17: [-1, 12, 9, 4, 33, 23] | G17: 38 | H17: 132.33697 | I17: [-1, 12, 9, 4, 33, 23] | J17: 38 | N17: 0.0053415298 | O17: [-1, 12, 9, 4, 23, 33] | P17: 38 | Q17: 40 | R17: [12, 37, 16] | S17: 2 | T17: 0.42644621 | U17: 38 | V17: 0 | W17: 0 | X17: 0
A18: 19 | B18: 4533.9694 | C18: [-1, 3, 33, 15, 32] | D18: 34 | E18: 43.429265 | F18: [-1, 27, 3] | G18: 34 | H18: 184.54431 | I18: [-1, 27, 3] | J18: 34 | N18: 0.0047674179 | O18: [-1, 27, 3] | P18: 34 | Q18: 40 | R18: [27, 33, 4] | S18: 6 | T18: 0.31949647 | U18: 34 | V18: 0 | W18: 0 | X18: 0
A19: 20 | B19: 86402.943 | E19: 75.783719 | F19: [-1, 2, 9] | G19: 36 | H19: 272.98981 | I19: [-1, 2, 9] | J19: 36 | N19: 0.0048246384 | O19: [-1, 2, 9] | P19: 36 | Q19: 40 | R19: [9, 2] | S19: 4 | T19: 1.051213 | U19: 36 | V19: 0 | W19: 0 | X19: 0
A20: 21 | E20: 148.4857 | F20: [-1, 2, 6, 36] | G20: 46 | H20: 742.77179 | I20: [-1, 2, 6, 36] | J20: 46 | N20: 0.0053641796 | O20: [-1, 2, 6, 36] | P20: 46 | Q20: 50 | R20: [2, 6, 36] | S20: 4 | T20: 0.70838133 | U20: 46 | V20: 0 | W20: 0 | X20: 0
A21: 22 | E21: 68.101652 | F21: [-1, 20, 49, 8] | G21: 49 | H21: 188.78203 | I21: [-1, 20, 49, 8] | J21: 49 | N21: 0.005525589 | O21: [-1, 8, 20] | P21: 48 | Q21: 50 | R21: [20, 49, 8] | S21: 1 | T21: 2.0549782 | U21: 49 | V21: 0 | W21: 0 | X21: 1
A22: 24 | E22: 132.75861 | F22: [-1, 5, 6, 25, 21, 37, 40] | G22: 48 | H22: 429.64812 | I22: [-1, 5, 6, 25, 21, 40, 37] | J22: 48 | N22: 0.0060706139 | O22: [-1, 5, 21, 25, 37, 40] | P22: 46 | Q22: 50 | R22: [6, 11, 10, 14, 43] | S22: 2 | T22: 1.6950052 | U22: 48 | V22: 0 | W22: 0 | X22: 2
A23: 26 | E23: 130.10778 | F23: [-1, 12, 36, 26] | G23: 45 | H23: 602.71775 | I23: [-1, 12, 36, 26] | J23: 45 | N23: 0.0056357384 | O23: [-1, 12, 26] | P23: 44 | Q23: 50 | R23: [12, 36, 26] | S23: 5 | T23: 1.5016255 | U23: 45 | V23: 0 | W23: 0 | X23: 1
A24: 27 | E24: 163.08274 | F24: [-1, 19, 1] | G24: 46 | H24: 833.21768 | I24: [-1, 19, 1] | J24: 46 | N24: 0.005720377 | O24: [-1, 19, 1] | P24: 46 | Q24: 50 | R24: [19, 1] | S24: 4 | T24: 0.66271328 | U24: 46 | V24: 0 | W24: 0 | X24: 0
A25: 29 | B25: 86400.255 | E25: 116.93431 | F25: [-1, 32, 6, 35] | G25: 47 | H25: 448.17442 | I25: [-1, 32, 35, 6] | J25: 47 | N25: 0.0055742264 | O25: [-1, 32, 35, 6] | P25: 47 | Q25: 50 | R25: [32, 35, 6] | S25: 3 | T25: 1.412417 | U25: 47 | V25: 0 | W25: 0 | X25: 0
A26: 30 | B26: 86400.26 | E26: 155.38067 | F26: [-1, 8, 48, 38] | G26: 44 | H26: 761.49398 | I26: [-1, 8, 48, 38] | J26: 44 | N26: 0.0060241222 | O26: [-1, 8, 48, 38] | P26: 44 | Q26: 50 | R26: [8, 48, 38] | S26: 6 | T26: 0.86279424 | U26: 44 | V26: 0 | W26: 0 | X26: 0
A27: 31 | E27: 636.5103 | F27: [-1, 73, 6] | G27: 71 | H27: 829.76647 | N27: 0.0072510242 | O27: [-1, 73, 6] | P27: 71 | Q27: 75 | R27: [73, 6] | S27: 4 | T27: 4.754549 | U27: 71 | V27: 0 | X27: 0
A28: 32 | E28: 801.98344 | F28: [-1, 5, 12] | G28: 71 | H28: 990.50533 | N28: 0.0071249008 | O28: [-1, 5, 12] | P28: 71 | Q28: 75 | R28: [5, 12] | S28: 4 | T28: 2.7697425 | U28: 71 | V28: 0 | X28: 0
A29: 33 | E29: 862.76423 | F29: [-1, 68, 30, 53] | G29: 72 | H29: 1056.4615 | N29: 0.0074980259 | O29: [-1, 68, 53] | P29: 71 | Q29: 75 | R29: [68, 30, 53] | S29: 3 | T29: 4.4461508 | U29: 72 | V29: 0 | X29: 1
A30: 34 | E30: 797.57794 | F30: [-1, 56, 45, 73] | G30: 74 | H30: 997.39091 | N30: 0.0074398518 | O30: [-1, 73, 56, 45] | P30: 74 | Q30: 75 | R30: [73, 56, 45] | S30: 1 | T30: 2.3383676 | U30: 74 | V30: 0 | X30: 0
A31: 35 | E31: 737.52451 | F31: [-1, 52, 12] | G31: 71 | H31: 947.69314 | N31: 0.0074191093 | O31: [-1, 52, 12] | P31: 71 | Q31: 75 | R31: [52, 12] | S31: 4 | T31: 3.9111923 | U31: 71 | V31: 0 | X31: 0
A32: 37 | E32: 859.7922 | F32: [-1, 5, 63, 50, 29] | G32: 69 | H32: 1054.3818 | N32: 0.0069537163 | O32: [-1, 5, 29] | P32: 65 | Q32: 75 | R32: [50, 63, 5, 29] | S32: 6 | T32: 10.330143 | U32: 69 | V32: 0 | X32: 4
A33: 38 | E33: 966.47409 | F33: [-1, 44, 2, 7] | G33: 73 | H33: 1181.814 | N33: 0.0067458153 | O33: [-1, 2, 7] | P33: 72 | Q33: 75 | R33: [50, 44, 53] | S33: 2 | T33: 13.40963 | U33: 73 | V33: 0 | X33: 1
A34: 39 | E34: 499.4171 | F34: [-1, 42, 38, 63, 31, 33] | G34: 69 | H34: 660.48237 | N34: 0.0071530342 | O34: [-1, 42, 63, 33, 31, 46] | P34: 68 | Q34: 75 | R34: [42, 63, 38, 31, 33] | S34: 6 | T34: 2.7420788 | U34: 69 | V34: 0 | X34: 1
A35: 41 | E35: 3565.7876 | F35: [-1, 58, 29, 38] | G35: 99 | H35: 4040.3333 | N35: 0.009118557 | O35: [-1, 38] | P35: 97 | Q35: 100 | R35: [58, 29, 38] | S35: 1 | T35: 25.949404 | U35: 99 | V35: 0 | X35: 2
A36: 42 | E36: 2059.7729 | F36: [-1, 46, 10] | G36: 97 | H36: 3022.9244 | N36: 0.0087280273 | O36: [-1, 46, 10] | P36: 97 | Q36: 100 | R36: [42, 18, 62, 70] | S36: 3 | T36: 10.904785 | U36: 97 | V36: 0 | X36: 0
A37: 43 | E37: 2591.8491 | F37: [-1, 12, 68, 98, 35] | G37: 96 | H37: 3170.6342 | N37: 0.0089905262 | O37: [-1, 68, 12, 98, 93] | P37: 95 | Q37: 100 | R37: [12, 68, 98, 35] | S37: 4 | T37: 13.080874 | U37: 96 | V37: 0 | X37: 1
A38: 44 | E38: 3300.5156 | F38: [-1, 3, 22, 16] | G38: 98 | H38: 3691.829 | N38: 0.0086023808 | O38: [-1, 22, 16, 62] | P38: 97 | Q38: 100 | R38: [3, 22, 16] | S38: 2 | T38: 9.2506277 | U38: 98 | V38: 0 | X38: 1
... A42: 50 | E42: 2685.7105 | F42: [-1, 94, 7, 84, 98] | G42: 96 | H42: 3183.6753 | N42: 0.0088996887 | O42: [-1, 94, 7, 84, 98] | P42: 96 | Q42: 100 | R42: [94, 7, 84, 98] | S42: 4 | T42: 5.9761223 | U42: 96 | V42: 0 | X42: 0
A43: 51 | B43: 0.066866159 | C43: [-1, 15, 0, 7, 13] | D43: 11 | E43: 9.0063677 | F43: [-1, 15, 0, 7, 13] | G43: 11 | H43: 15.144894 | I43: [-1, 15, 0, 11, 12, 13] | J43: 11 | K43: 26759.82 | L43: [-1, 15, 11, 0, 13, 12, 1, 6] | M43: 11 | N43: 0.0042831898 | O43: [-1, 15, 7, 13] | P43: 10 | Q43: 20 | R43: [15, 11, 0, 13, 12] | S43: 9 | T43: 0.035263192 | U43: 11 | V43: 0 | W43: 0 | X43: 1
...

Sheet solution
A1: experiment | B1: solution_iqcp | C1: solution_rollout k=1 | D1: solution_rollout k=2 | E1: solution_rollout k=3
A2: 1 | B2: [-1, 2, 3] | C2: [23, 2, 21, 19] | D2: [23, 2, 21, 19] | E2: [23, 2, 21, 19]
A3: 2 | B3: [-1, 18, 21, 19] | C3: [18, 21, 19] | D3: [18, 21, 19] | E3: [18, 21, 19]
A4: 3 | B4: [-1, 10] | C4: [10] | D4: [10] | E4: [10]
A5: 4 | B5: [-1, 11, 5, 2, 4] | C5: [1, 16, 23] | D5: [1, 16, 23] | E5: [1, 16, 23]
A6: 5 | B6: [-1, 8] | C6: [8] | D6: [8] | E6: [8]
A7: 6 | B7: [-1, 0, 2, 17] | C7: [0, 2, 17] | D7: [0, 2, 17] | E7: [0, 2, 17]
A8: 7 | B8: [-1, 7, 10, 8, 9] | C8: [7, 10, 8, 9] | D8: [7, 10, 8, 9] | E8: [7, 10, 8, 9]
A9: 8 | B9: [-1, 4, 17, 13] | C9: [4, 17, 13] | D9: [4, 17, 13] | E9: [4, 17, 13]
A10: 9 | B10: [-1, 6, 24, 15, 23] | C10: [6, 24, 15, 23] | D10: [6, 24, 15, 23] | E10: [6, 24, 15, 23]
A11: 10 | B11: [-1, 15, 13, 5, 17] | C11: [15, 12, 11, 22] | D11: [15, 12, 11, 22] | E11: [15, 12, 11, 22]
A12: 11 | B12: [-1, 38, 26, 11, 15, 8, 7] | C12: [38, 32, 33, 8, 7] | D12: [38, 32, 33, 8, 7] | E12: [38, 32, 33, 8, 7]
A13: 12 | B13: [-1, 34] | C13: [34] | D13: [34] | E13: [34]
... A61: 60 | B61: [-1, 4, 1] | C61: [4, 1] | D61: [4, 1] | E61: [4, 1]

Sheet optimos
A1: experiment | B1: n_nodes | C1: optimal_dp | D1: optimal_iqcp | E1: ilp | F1: optimal_miqcp | G1: optimal_greedy | H1: optimal_rollout k=1 | I1: optimal_rollout k=2 | J1: optimal_rollout k=3
A2: 1 | B2: 25 | C2: 16 | D2: 16 | E2: 16 | F2: 16 | G2: 16 | H2: 16 | I2: 16 | J2: 16
A3: 2 | B3: 25 | C3: 20 | D3: 20 | E3: 20 | G3: 19 | H3: 20 | I3: 20 | J3: 20
A4: 3 | B4: 25 | C4: 21 | D4: 21 | E4: 21 | F4: 21 | G4: 21 | H4: 21 | I4: 21 | J4: 21
A5: 4 | B5: 25 | C5: 18 | D5: 18 | E5: 18 | F5: 18 | G5: 17 | H5: 17 | I5: 17 | J5: 17
A6: 5 | B6: 25 | C6: 22 | D6: 22 | E6: 22 | F6: 22 | G6: 22 | H6: 22 | I6: 22 | J6: 22
A7: 6 | B7: 25 | C7: 19 | D7: 19 | E7: 19 | G7: 19 | H7: 19 | I7: 19 | J7: 19
A8: 7 | B8: 25 | C8: 18 | D8: 18 | E8: 18 | G8: 18 | H8: 18 | I8: 18 | J8: 18
A9: 8 | B9: 25 | C9: 19 | D9: 19 | E9: 19 | G9: 19 | H9: 19 | I9: 19 | J9: 19
A10: 9 | B10: 25 | C10: 18 | D10: 18 | E10: 18 | G10: 18 | H10: 18 | I10: 18 | J10: 18
A11: 10 | B11: 25 | C11: 20 | D11: 20 | E11: 20 | G11: 12 | H11: 20 | I11: 20 | J11: 20
A12: 11 | B12: 40 | C12: 36 | D12: 36 | E12: 36 | G12: 31 | H12: 36 | I12: 36 | J12: 36
A13: 12 | B13: 40 | C13: 36 | D13: 36 | E13: 36 | G13: 36 | H13: 36 | I13: 36 | J13: 36
A14: 13 | B14: 40 | D14: 38 | E14: 38 | G14: 38 | H14: 38 | I14: 38 | J14: 38
A15: 14 | B15: 40 | C15: 39 | D15: 39 | E15: 39 | G15: 39 | H15: 39 | I15: 39 | J15: 39
A16: 15 | B16: 40 | C16: 36 | D16: 36 | E16: 36 | G16: 36 | H16: 36 | I16: 36 | J16: 36
A17: 16 | B17: 40 | C17: 34 | D17: 34 | E17: 34 | G17: 33 | H17: 34 | I17: 34 | J17: 34
A18: 17 | B18: 40 | C18: 36 | D18: 36 | E18: 36 | G18: 35 | H18: 35 | I18: 36 | J18: 36
A19: 18 | B19: 40 | C19: 38 | D19: 38 | E19: 38 | G19: 38 | H19: 38 | I19: 38 | J19: 38
A20: 19 | B20: 40 | C20: 34 | D20: 34 | E20: 34 | G20: 34 | H20: 34 | I20: 34 | J20: 34
A21: 20 | B21: 40 | D21: 36 | E21: 36 | G21: 36 | H21: 36 | I21: 36 | J21: 36
A22: 21 | B22: 50 | D22: 46 | E22: 46 | G22: 46 | H22: 46 | I22: 46 | J22: 46
A23: 22 | B23: 50 | D23: 49 | E23: 49 | G23: 48 | H23: 49 | I23: 49 | J23: 49
A24: 23 | B24: 50 | D24: 48 | E24: 48 | G24: 47 | H24: 47 | I24: 48 | J24: 48
A25: 24 | B25: 50 | D25: 48 | E25: 48 | G25: 46 | H25: 48 | I25: 48 | J25: 48
A26: 25 | B26: 50 | D26: 44 | E26: 44 | G26: 42 | H26: 43 | I26: 44 | J26: 44
A27: 26 | B27: 50 | D27: 45 | E27: 45 | G27: 44 | H27: 45 | I27: 45 | J27: 45
A28: 27 | B28: 50 | D28: 46 | E28: 46 | G28: 46 | H28: 46 | I28: 46 | J28: 46
A29: 28 | B29: 50 | D29: 47 | E29: 47 | G29: 46 | H29: 46 | I29: 46 | J29: 46
A30: 29 | B30: 50 | D30: 47 | E30: 47 | G30: 47 | H30: 47 | I30: 47 | J30: 47
A31: 30 | B31: 50 | D31: 44 | E31: 44 | G31: 44 | H31: 44 | I31: 44 | J31: 44
A32: 31 | B32: 75 | D32: 71 | G32: 71 | H32: 71 | I32: 71 | J32: 71
A33: 32 | B33: 75 | D33: 71 | G33: 71 | H33: 71 | I33: 71 | J33: 71
A34: 33 | B34: 75 | D34: 72 | G34: 71 | H34: 72 | I34: 72 | J34: 72
A35: 34 | B35: 75 | D35: 74 | G35: 74 | H35: 74 | I35: 74 | J35: 74
A36: 35 | B36: 75 | D36: 71 | G36: 71 | H36: 71 | I36: 71 | J36: 71
A37: 36 | B37: 75 | D37: 65 | G37: 59 | H37: 64 | I37: 64 | J37: 65
A38: 37 | B38: 75 | D38: 69 | G38: 65 | H38: 69 | I38: 69 | J38: 69
A39: 38 | B39: 75 | D39: 73 | G39: 72 | H39: 73 | I39: 73 | J39: 73
A40: 39 | B40: 75 | D40: 69 | G40: 68 | H40: 69 | I40: 69 | J40: 69
...

Sheet duracion
A1: experiment | B1: duration_dp | C1: duration_iqcp | D1: duration | E1: duration_miqcp | F1: duration_greedy | G1: time_taken k=1 | H1: time_taken k=2 | I1: time_taken k=3 | J1: n-nodos
A2: 1 | B2: 0.17613745 | C2: 13.040887 | D2: 47.843506 | E2: 23232.208 | F2: 0.014831305 | G2: 0.10971253 | H2: 0.24466503 | I2: 0.30879185 | J2: 25
A3: 2 | B3: 0.15577698 | C3: 5.0183191 | D3: 17.926093 | E3: 86400.072 | F3: 0.004509449 | G3: 0.11747764 | H3: 0.52612253 | I3: 0.60000324 | J3: 25
A4: 3 | B4: 3.4204645 | C4: 10.010939 | D4: 17.00809 | E4: 1425.4224 | F4: 0.0040242672 | G4: 0.08475813 | H4: 0.45713655 | I4: 0.6842962 | J4: 25
A5: 4 | B5: 0.35159588 | C5: 8.5404961 | D5: 27.014186 | E5: 79622.902 | F5: 0.0041053295 | G5: 0.057115339 | H5: 0.065240531 | I5: 0.061295366 | J5: 25
A6: 5 | B6: 1.7921865 | C6: 10.067082 | D6: 20.000447 | E6: 43438.653 | F6: 0.0041453838 | G6: 0.063388106 | H6: 0.45006092 | I6: 0.53941636 | J6: 25
A7: 6 | B7: 0.19284844 | C7: 10.538142 | D7: 37.179535 | E7: 86400.036 | F7: 0.0046305656 | G7: 0.065004193 | H7: 0.17228873 | I7: 0.23622382 | J7: 25
A8: 7 | B8: 2.0427024 | C8: 13.685847 | D8: 43.679956 | E8: 86400.141 | F8: 0.004298687 | G8: 0.072989716 | H8: 0.36620988 | I8: 0.82860089 | J8: 25
A9: 8 | B9: 1.8801317 | C9: 15.032512 | D9: 35.265093 | E9: 86400.196 | F9: 0.0043210983 | G9: 0.081918735 | H9: 0.33166469 | I9: 0.70843771 | J9: 25
A10: 9 | B10: 0.31319165 | C10: 27.342374 | D10: 46.145465 | E10: 86400.132 | F10: 0.0044243336 | G10: 0.082151051 | H10: 0.21359489 | I10: 0.25433833 | J10: 25
A11: 10 | B11: 0.11955214 | C11: 8.4801874 | D11: 30.69507 | E11: 86400.117 | F11: 0.0041575432 | G11: 0.080581652 | H11: 0.29245951 | I11: 0.3628893 | J11: 25
A12: 11 | B12: 756.5457 | C12: 78.926251 | D12: 336.39173 | F12: 0.0050559044 | G12: 0.50610813 | H12: 2.7042358 | I12: 3.8715406 | J12: 40
A13: 12 | B13: 10313.59 | C13: 57.669784 | D13: 124.70194 | F13: 0.0047380924 | G13: 0.53833238 | H13: 7.653823 | I13: 13.864558 | J13: 40
A14: 13 | B14: 86400.276 | C14: 92.590263 | D14: 196.18166 | F14: 0.0048034191 | G14: 0.60947378 | H14: 3.7199466 | I14: 14.843964 | J14: 40
A15: 14 | B15: 2821.6056 | C15: 49.555662 | D15: 110.5152 | F15: 0.0050327778 | G15: 0.25606458 | H15: 4.0097473 | I15: 16.021238 | J15: 40
A16: 15 | B16: 19938.966 | C16: 68.489383 | D16: 240.73659 | F16: 0.0049045086 | G16: 0.35657852 | H16: 3.8634364 | I16: 5.1966463 | J16: 40
A17: 16 | B17: 430.32573 | C17: 58.67364 | D17: 262.88486 | F17: 0.0048835278 | G17: 0.61351311 | H17: 3.99774 | I17: 5.4381008 | J17: 40
A18: 17 | B18: 3930.6082 | C18: 58.510286 | D18: 241.10887 | F18: 0.0047316551 | G18: 0.46743824 | H18: 3.0997107 | I18: 3.9884954 | J18: 40
A19: 18 | B19: 3804.9753 | C19: 57.792312 | D19: 132.33697 | F19: 0.0053415298 | G19: 0.42644621 | H19: 3.333871 | I19: 6.879325 | J19: 40
A20: 19 | B20: 4533.9694 | C20: 43.429265 | D20: 184.54431 | F20: 0.0047674179 | G20: 0.31949647 | H20: 3.6266726 | I20: 3.6670311 | J20: 40
A21: 20 | B21: 86402.943 | C21: 75.783719 | D21: 272.98981 | F21: 0.0048246384 | G21: 1.051213 | H21: 6.3375546 | I21: 17.771455 | J21: 40
A22: 21 | C22: 148.4857 | D22: 742.77179 | F22: 0.0053641796 | G22: 0.70838133 | H22: 10.779287 | I22: 52.139467 | J22: 50
A23: 22 | C23: 68.101652 | D23: 188.78203 | F23: 0.005525589 | G23: 2.0549782 | H23: 18.903278 | I23: 28.750692 | J23: 50
A24: 23 | C24: 163.80629 | D24: 625.07527 | F24: 0.0056612492 | G24: 1.6299016 | H24: 14.888578 | I24: 40.868352 | J24: 50
A25: 24 | C25: 132.75861 | D25: 429.64812 | F25: 0.0060706139 | G25: 1.6950052 | H25: 12.061165 | I25: 48.376064 | J25: 50
A26: 25 | C26: 671.9996 | D26: 2373.3998 | F26: 0.0057797432 | G26: 0.74324567 | H26: 7.8897137 | I26: 24.074461 | J26: 50
A27: 26 | C27: 130.10778 | D27: 602.71775 | F27: 0.0056357384 | G27: 1.5016255 | H27: 22.798348 | I27: 54.28792 | J27: 50
A28: 27 | C28: 163.08274 | D28: 833.21768 | F28: 0.005720377 | G28: 0.66271328 | H28: 6.7705857 | I28: 7.8249889 | J28: 50
A29: 28 | C29: 133.62735 | D29: 517.27749 | F29: 0.0057938099 | G29: 1.0895802 | H29: 9.8600171 | I29: 11.467731 | J29: 50
A30: 29 | B30: 86400.255 | C30: 116.93431 | D30: 448.17442 | F30: 0.0055742264 | G30: 1.412417 | H30: 18.706617 | I30: 44.995577 | J30: 50
A31: 30 | B31: 86400.26 | C31: 155.38067 | D31: 761.49398 | F31: 0.0060241222 | G31: 0.86279424 | H31: 8.0576837 | I31: 15.43724 | J31: 50
A32: 31 | C32: 636.5103 | D32: 829.76647 | F32: 0.0072510242 | G32: 4.754549 | H32: 58.799351 | I32: 79.297554 | J32: 75
A33: 32 | C33: 801.98344 | D33: 990.50533 | F33: 0.0071249008 | G33: 2.7697425 | H33: 81.517056 | I33: 288.05232 | J33: 75
A34: 33 | C34: 862.76423 | D34: 1056.4615 | F34: 0.0074980259 | G34: 4.4461508 | H34: 110.24851 | I34: 614.91762 | J34: 75
A35: 34 | C35: 797.57794 | D35: 997.39091 | F35: 0.0074398518 | G35: 2.3383676 | H35: 61.72112 | I35: 218.6805 | J35: 75
A36: 35 | C36: 737.52451 | D36: 947.69314 | F36: 0.0074191093 | G36: 3.9111923 | H36: 84.957753 | I36: 192.85137 | J36: 75
A37: 36 | C37: 12748.104 | D37: 1018.6011 | F37: 0.0076315403 | G37: 1.7444736 | H37: 12.165388 | I37: 17.534094 | J37: 75
A38: 37 | C38: 859.7922 | D38: 1054.3818 | F38: 0.0069537163 | G38: 10.330143 | H38: 103.11256 | I38: 258.26638 | J38: 75
A39: 38 | C39: 966.47409 | D39: 1181.814 | F39: 0.0067458153 | G39: 13.40963 | H39: 134.36286 | I39: 517.46353 | J39: 75
A40: 39 | C40: 499.4171 | D40: 660.48237 | F40: 0.0071530342 | G40: 2.7420788 | H40: 27.877431 | I40: 54.713471 | J40: 75
...

Sheet comparaciones
A1: Nodos | B1: Instancias | C1: Prom. Nodos salvados óptimo IQCP | D1: Greedy | E1: Prom. Nodos salvados Rollout k=1 | F1: Prom. Nodos salvados Rollout k=2 | G1: Prom. Nodos salvados Rollout k=3 | H1: GAP Rollout k=1 | I1: GAP Rollout k=2 | J1: GAP Rollout k=3
A2: 20 | B2: 10 | C2: =AVERAGEIF(Table1[n_nodes],comparaciones!A2,Table1[optimal_iqcp]) -> 14.7 | D2: =AVERAGEIF(Table1[n_nodes],A2,Table1[optimal_greedy]) -> 13.8 | E2: =AVERAGEIF(Table2[n_nodes],comparaciones!A2,Table2[optimal_rollout k=1]) -> 14.6 | F2: =AVERAGEIF(Table2[n_nodes],comparaciones!A2,Table2[optimal_rollout k=2]) -> 14.6 | G2: =AVERAGEIF(Table2[n_nodes],comparaciones!A2,Table2[optimal_rollout k=3]) -> 14.6 | H2: =(C2-E2)/C2 -> 0.0068027211 | I2: =(C2-F2)/C2 -> 0.0068027211 | J2: =(C2-G2)/C2 -> 0.0068027211
A3: 25 | B3: 10 | C3: =AVERAGEIF(Table1[n_nodes],comparaciones!A3,Table1[optimal_iqcp]) -> 19.1 | D3: =AVERAGEIF(Table1[n_nodes],A3,Table1[optimal_greedy]) -> 18.1 | E3: =AVERAGEIF(Table2[n_nodes],comparaciones!A3,Table2[optimal_rollout k=1]) -> 19 | F3: =AVERAGEIF(Table2[n_nodes],comparaciones!A3,Table2[optimal_rollout k=2]) -> 19 | G3: =AVERAGEIF(Table2[n_nodes],comparaciones!A3,Table2[optimal_rollout k=3]) -> 19 | H3: =(C3-E3)/C3 -> 0.0052356021 | I3: =(C3-F3)/C3 -> 0.0052356021 | J3: =(C3-G3)/C3 -> 0.0052356021
A4: 40 | B4: 10 | C4: =AVERAGEIF(Table1[n_nodes],comparaciones!A4,Table1[optimal_iqcp]) -> 36.3 | D4: =AVERAGEIF(Table1[n_nodes],A4,Table1[optimal_greedy]) -> 35.6 | E4: =AVERAGEIF(Table2[n_nodes],comparaciones!A4,Table2[optimal_rollout k=1]) -> 36.2 | F4: =AVERAGEIF(Table2[n_nodes],comparaciones!A4,Table2[optimal_rollout k=2]) -> 36.3 | G4: =AVERAGEIF(Table2[n_nodes],comparaciones!A4,Table2[optimal_rollout k=3]) -> 36.3 | H4: =(C4-E4)/C4 -> 0.0027548209 | I4: =(C4-F4)/C4 -> 0 | J4: =(C4-G4)/C4 -> 0
A5: 50 | B5: 10 | C5: =AVERAGEIF(Table1[n_nodes],comparaciones!A5,Table1[optimal_iqcp]) -> 46.4 | D5: =AVERAGEIF(Table1[n_nodes],A5,Table1[optimal_greedy]) -> 45.6 | E5: =AVERAGEIF(Table2[n_nodes],comparaciones!A5,Table2[optimal_rollout k=1]) -> 46.1 | F5: =AVERAGEIF(Table2[n_nodes],comparaciones!A5,Table2[optimal_rollout k=2]) -> 46.3 | G5: =AVERAGEIF(Table2[n_nodes],comparaciones!A5,Table2[optimal_rollout k=3]) -> 46.3 | H5: =(C5-E5)/C5 -> 0.0064655172 | I5: =(C5-F5)/C5 -> 0.0021551724 | J5: =(C5-G5)/C5 -> 0.0021551724
A6: 75 | B6: 10 | C6: =AVERAGEIF(Table1[n_nodes],comparaciones!A6,Table1[optimal_iqcp]) -> 70.4 | D6: =AVERAGEIF(Table1[n_nodes],A6,Table1[optimal_greedy]) -> 68.4 | E6: =AVERAGEIF(Table2[n_nodes],comparaciones!A6,Table2[optimal_rollout k=1]) -> 70.2 | F6: =AVERAGEIF(Table2[n_nodes],comparaciones!A6,Table2[optimal_rollout k=2]) -> 70.2 | G6: =AVERAGEIF(Table2[n_nodes],comparaciones!A6,Table2[optimal_rollout k=3]) -> 70.3 | H6: =(C6-E6)/C6 -> 0.0028409091 | I6: =(C6-F6)/C6 -> 0.0028409091 | J6: =(C6-G6)/C6 -> 0.0014204545
A7: 100 | B7: 10 | C7: =AVERAGEIF(Table1[n_nodes],comparaciones!A7,Table1[optimal_iqcp]) -> 95.9 | D7: =AVERAGEIF(Table1[n_nodes],A7,Table1[optimal_greedy]) -> 94.6 | E7: =AVERAGEIF(Table2[n_nodes],comparaciones!A7,Table2[optimal_rollout k=1]) -> 95.8 | F7: =AVERAGEIF(Table2[n_nodes],comparaciones!A7,Table2[optimal_rollout k=2]) -> 95.8 | G7: =AVERAGEIF(Table2[n_nodes],comparaciones!A7,Table2[optimal_rollout k=3]) -> 95.8 | H7: =(C7-E7)/C7 -> 0.0010427529 | I7: =(C7-F7)/C7 -> 0.0010427529 | J7: =(C7-G7)/C7 -> 0.0010427529
A12: Nodos | B12: Instancias | C12: Prom. T-CPU MIQCP | D12: Prom. T-CPU IQCP | E12: Prom. T-CPU ILP | F12: Prom. T-CPU Greedy | G12: Prom. T-CPU Rollout k=1 | H12: Prom. T-CPU Rollout k=2 | I12: Prom. T-CPU Rollout k=3
A13: 20 | B13: 10 | C13: =AVERAGEIF(Table1[n_nodes],comparaciones!A13,Table1[duration_miqcp]) -> 37825.712 | D13: =AVERAGEIF(Table1[n_nodes],comparaciones!A13,Table1[duration_iqcp]) -> 4.7960814 | E13: =AVERAGEIF(Table1[n_nodes],comparaciones!A13,Table1[duration]) -> 11.439051 | F13: =AVERAGEIF(Table1[n_nodes],comparaciones!A13,Table1[duration_greedy]) -> 0.003666544 | G13: =AVERAGEIF(Table3[n-nodos],comparaciones!A13,Table3[time_taken k=1 ]) -> 0.038371206 | H13: =AVERAGEIF(Table3[n-nodos],A13,Table3[time_taken k=2]) -> 0.12913123 | I13: =AVERAGEIF(Table3[n-nodos],A13,Table3[time_taken k=3]) -> 0.17160891
A14: 25 | B14: 10 | C14: =AVERAGEIF(Table1[n_nodes],comparaciones!A14,Table1[duration_miqcp]) -> 66611.988 | D14: =AVERAGEIF(Table1[n_nodes],comparaciones!A14,Table1[duration_iqcp]) -> 12.175679 | E14: =AVERAGEIF(Table1[n_nodes],comparaciones!A14,Table1[duration]) -> 32.275744 | F14: =AVERAGEIF(Table1[n_nodes],comparaciones!A14,Table1[duration_greedy]) -> 0.0053447962 | G14: =AVERAGEIF(Table3[n-nodos],comparaciones!A14,Table3[time_taken k=1 ]) -> 0.081509709 | H14: =AVERAGEIF(Table3[n-nodos],A14,Table3[time_taken k=2]) -> 0.31194433 | I14: =AVERAGEIF(Table3[n-nodos],A14,Table3[time_taken k=3]) -> 0.4584293
A15: 40 | B15: 10 | C15: - | D15: =AVERAGEIF(Table1[n_nodes],comparaciones!A15,Table1[duration_iqcp]) -> 64.142056 | E15: =AVERAGEIF(Table1[n_nodes],comparaciones!A15,Table1[duration]) -> 210.2392 | F15: =AVERAGEIF(Table1[n_nodes],comparaciones!A15,Table1[duration_greedy]) -> 0.0049083471 | G15: =AVERAGEIF(Table3[n-nodos],comparaciones!A15,Table3[time_taken k=1 ]) -> 0.51446644 | H15: =AVERAGEIF(Table3[n-nodos],A15,Table3[time_taken k=2]) -> 4.2346738 | I15: =AVERAGEIF(Table3[n-nodos],A15,Table3[time_taken k=3]) -> 9.1542353
A16: 50 | B16: 10 | C16: - | D16: =AVERAGEIF(Table1[n_nodes],comparaciones!A16,Table1[duration_iqcp]) -> 188.42847 | E16: =AVERAGEIF(Table1[n_nodes],comparaciones!A16,Table1[duration]) -> 752.25583 | F16: =AVERAGEIF(Table1[n_nodes],comparaciones!A16,Table1[duration_greedy]) -> 0.0057149649 | G16: =AVERAGEIF(Table3[n-nodos],comparaciones!A16,Table3[time_taken k=1 ]) -> 1.2360642 | H16: =AVERAGEIF(Table3[n-nodos],A16,Table3[time_taken k=2]) -> 13.071527 | I16: =AVERAGEIF(Table3[n-nodos],A16,Table3[time_taken k=3]) -> 32.822249
A17: 75 | B17: 10 | C17: - | D17: =AVERAGEIF(Table1[n_nodes],comparaciones!A17,Table1[duration_iqcp]) -> 2021.6529 | E17: =AVERAGEIF(Table1[n_nodes],comparaciones!A17,Table1[duration]) -> 963.23044 | F17: =AVERAGEIF(Table1[n_nodes],comparaciones!A17,Table1[duration_greedy]) -> 0.0072853565 | G17: =AVERAGEIF(Table3[n-nodos],comparaciones!A17,Table3[time_taken k=1 ]) -> 5.0029981 | H17: =AVERAGEIF(Table3[n-nodos],A17,Table3[time_taken k=2]) -> 69.574909 | I17: =AVERAGEIF(Table3[n-nodos],A17,Table3[time_taken k=3]) -> 229.47274
A18: 100 | B18: 10 | C18: - | D18: =AVERAGEIF(Table1[n_nodes],comparaciones!A18,Table1[duration_iqcp]) -> 3171.4132 | E18: =AVERAGEIF(Table1[n_nodes],comparaciones!A18,Table1[duration]) -> 3318.0467 | F18: =AVERAGEIF(Table1[n_nodes],comparaciones!A18,Table1[duration_greedy]) -> 0.0089655399 | G18: =AVERAGEIF(Table3[n-nodos],comparaciones!A18,Table3[time_taken k=1 ]) -> 11.379563 | H18: =AVERAGEIF(Table3[n-nodos],A18,Table3[time_taken k=2]) -> 235.63979 | I18: =AVERAGEIF(Table3[n-nodos],A18,Table3[time_taken k=3]) -> 939.06461
